package com.InfinityRaider.AgriCraft.world;

import com.InfinityRaider.AgriCraft.handler.ConfigurationHandler;
import com.InfinityRaider.AgriCraft.tileentity.TileEntityCrop;
import com.InfinityRaider.AgriCraft.tileentity.TileEntitySeedAnalyzer;
import com.InfinityRaider.AgriCraft.utility.LogHelper;
import com.InfinityRaider.AgriCraft.utility.SeedHelper;
import net.minecraft.init.Blocks;
import net.minecraft.item.ItemSeeds;
import net.minecraft.item.ItemStack;
import net.minecraft.util.WeightedRandomChestContent;
import net.minecraft.world.World;
import net.minecraft.world.gen.structure.StructureBoundingBox;
import net.minecraft.world.gen.structure.StructureComponent;
import net.minecraft.world.gen.structure.StructureVillagePieces;
import net.minecraftforge.common.util.ForgeDirection;

import java.util.List;
import java.util.Random;

public class StructureGreenhouse extends StructureVillagePieces.House1 {
    //structure dimensions
    private static final int xSize = 17;
    private static final int ySize = 10;
    private static final int zSize = 11;
    //helper fields
    private int averageGroundLevel = -1;

    public StructureGreenhouse() {}

    public StructureGreenhouse(StructureVillagePieces.Start villagePiece, int nr, Random rand, StructureBoundingBox structureBoundingBox, int coordBaseMode) {
        super();
        this.coordBaseMode = coordBaseMode;
        this.boundingBox = structureBoundingBox;
    }
    //public method to build the component
    public static StructureGreenhouse buildComponent(StructureVillagePieces.Start villagePiece, List pieces, Random random, int p1, int p2, int p3, int p4, int p5) {
        StructureBoundingBox boundingBox = StructureBoundingBox.getComponentToAddBoundingBox(p1, p2, p3, 0, 0, 0, xSize, ySize, zSize, p4);
        return (canVillageGoDeeper(boundingBox)) && (StructureComponent.findIntersecting(pieces, boundingBox) == null)?new StructureGreenhouse(villagePiece, p5, random, boundingBox, p4) : null;
    }
    //structure generation code
    @Override
    public boolean addComponentParts(World world, Random rand, StructureBoundingBox boundingBox) {
        //level off ground
        if (this.averageGroundLevel < 0) {
            this.averageGroundLevel = getAverageGroundLevel(world, boundingBox);
            if (this.averageGroundLevel < 0) {
                return true;
            }
            this.boundingBox.offset(0, this.averageGroundLevel - this.boundingBox.maxY + 7, 0);
        }
        //cobblestone base
        this.fillWithBlocks(world, boundingBox, 0, 0, 0, xSize - 1, 0, zSize - 1, Blocks.cobblestone, Blocks.cobblestone, false);   //args: (world, boundingBox, minX, minY, MinZ, maxX, maxY, maxZ, placeBlock, replaceBlock, doReplace)
        //ring of gravel
        this.fillWithBlocks(world, boundingBox, 0, 1, 0, xSize - 1, 1, 0, Blocks.gravel, Blocks.gravel, false);
        this.fillWithBlocks(world, boundingBox, 0, 1, 0, 0, 1, zSize - 1, Blocks.gravel, Blocks.gravel, false);
        this.fillWithBlocks(world, boundingBox, 0, 1, zSize - 1, xSize - 1, 1, zSize - 1, Blocks.gravel, Blocks.gravel, false);
        this.fillWithBlocks(world, boundingBox, xSize - 1, 1, 0, xSize - 1, 1, zSize - 1, Blocks.gravel, Blocks.gravel, false);
        //cobble foundations
        this.fillWithBlocks(world, boundingBox, 1, 1, 1, 1, 1, 4, Blocks.cobblestone, Blocks.cobblestone, false);
        this.fillWithBlocks(world, boundingBox, 1, 1, 6, 1, 1, 9, Blocks.cobblestone, Blocks.cobblestone, false);
        this.fillWithBlocks(world, boundingBox, 15, 1, 1, 15, 1, 4, Blocks.cobblestone, Blocks.cobblestone, false);
        this.fillWithBlocks(world, boundingBox, 15, 1, 6, 15, 1, 9, Blocks.cobblestone, Blocks.cobblestone, false);
        this.placeBlockAtCurrentPosition(world, Blocks.cobblestone, 0, 2, 1, 1, boundingBox);
        this.placeBlockAtCurrentPosition(world, Blocks.cobblestone, 0, 8, 1, 1, boundingBox);
        this.placeBlockAtCurrentPosition(world, Blocks.cobblestone, 0, 14, 1, 5, boundingBox);
        this.placeBlockAtCurrentPosition(world, Blocks.cobblestone, 0, 2, 1, 9, boundingBox);
        this.placeBlockAtCurrentPosition(world, Blocks.cobblestone, 0, 8, 1, 9, boundingBox);
        this.placeBlockAtCurrentPosition(world, Blocks.cobblestone, 0, 14, 1, 9, boundingBox);
        //place slabs
        this.placeBlockAtCurrentPosition(world, Blocks.double_stone_slab, 0, 1, 1, 5, boundingBox);
        this.placeBlockAtCurrentPosition(world, Blocks.double_stone_slab, 0, 15, 1, 5, boundingBox);
        this.fillWithBlocks(world, boundingBox, 2, 1, 2, 2, 1, 8, Blocks.double_stone_slab, Blocks.double_stone_slab, false);
        this.fillWithBlocks(world, boundingBox, 8, 1, 2, 8, 1, 8, Blocks.double_stone_slab, Blocks.double_stone_slab, false);
        this.fillWithBlocks(world, boundingBox, 14, 1, 2, 14, 1, 8, Blocks.double_stone_slab, Blocks.double_stone_slab, false);
        this.fillWithBlocks(world, boundingBox, 2, 1, 2, 14, 1, 2, Blocks.double_stone_slab, Blocks.double_stone_slab, false);
        this.fillWithBlocks(world, boundingBox, 2, 1, 8, 14, 1, 8, Blocks.double_stone_slab, Blocks.double_stone_slab, false);
        //place water
        this.fillWithBlocks(world, boundingBox, 3, 1, 1, 7, 1, 1, Blocks.water, Blocks.water, false);
        this.fillWithBlocks(world, boundingBox, 9, 1, 1, 10, 1, 1, Blocks.water, Blocks.water, false);
        this.fillWithBlocks(world, boundingBox, 3, 1, 9, 7, 1, 9, Blocks.water, Blocks.water, false);
        this.fillWithBlocks(world, boundingBox, 9, 1, 9, 13, 1, 9, Blocks.water, Blocks.water, false);
        this.placeBlockAtCurrentPosition(world, Blocks.water, 0, 13, 1, 6, boundingBox);
        //place farmland
        this.fillWithMetadataBlocks(world, boundingBox, 3, 1, 3, 7, 1, 7, Blocks.farmland, 7, Blocks.farmland, 7, false);
        this.fillWithMetadataBlocks(world, boundingBox, 9, 1, 3, 13, 1, 7, Blocks.farmland, 7, Blocks.farmland, 7, false);
        //place standing logs
        this.fillWithMetadataBlocks(world, boundingBox, 1, 2, 1, 1, 6, 1, Blocks.log, 0, Blocks.log, 0, false);
        this.fillWithMetadataBlocks(world, boundingBox, 8, 2, 1, 8, 6, 1, Blocks.log, 0, Blocks.log, 0, false);
        this.fillWithMetadataBlocks(world, boundingBox, 15, 2, 1, 15, 6, 1, Blocks.log, 0, Blocks.log, 0, false);
        this.fillWithMetadataBlocks(world, boundingBox, 1, 2, 4, 1, 5, 4, Blocks.log, 0, Blocks.log, 0, false);
        this.fillWithMetadataBlocks(world, boundingBox, 15, 2, 4, 15, 5, 4, Blocks.log, 0, Blocks.log, 0, false);
        this.fillWithMetadataBlocks(world, boundingBox, 1, 2, 6, 1, 5, 6, Blocks.log, 0, Blocks.log, 0, false);
        this.fillWithMetadataBlocks(world, boundingBox, 15, 2, 6, 15, 5, 6, Blocks.log, 0, Blocks.log, 0, false);
        this.fillWithMetadataBlocks(world, boundingBox, 1, 2, 9, 1, 6, 9, Blocks.log, 0, Blocks.log, 0, false);
        this.fillWithMetadataBlocks(world, boundingBox, 8, 2, 9, 8, 6, 9, Blocks.log, 0, Blocks.log, 0, false);
        this.fillWithMetadataBlocks(world, boundingBox, 15, 2, 9, 15, 6, 9, Blocks.log, 0, Blocks.log, 0, false);
        //logs along x-axis
        this.fillWithMetadataBlocks(world, boundingBox, 2, 6, 1, 7, 6, 1, Blocks.log, 4, Blocks.log, 4, false);
        this.fillWithMetadataBlocks(world, boundingBox, 9, 6, 1, 14, 6, 1, Blocks.log, 4, Blocks.log, 4, false);
        this.fillWithMetadataBlocks(world, boundingBox, 2, 6, 9, 7, 6, 9, Blocks.log, 4, Blocks.log, 4, false);
        this.fillWithMetadataBlocks(world, boundingBox, 9, 6, 9, 14, 6, 9, Blocks.log, 4, Blocks.log, 4, false);
        //logs along z-axis
        this.fillWithMetadataBlocks(world, boundingBox, 1, 6, 2, 1, 6, 8, Blocks.log, 8, Blocks.log, 8, false);
        this.fillWithMetadataBlocks(world, boundingBox, 8, 6, 2, 8, 6, 8, Blocks.log, 8, Blocks.log, 8, false);
        this.fillWithMetadataBlocks(world, boundingBox, 15, 6, 2, 15, 6, 8, Blocks.log, 8, Blocks.log, 8, false);
        this.placeBlockAtCurrentPosition(world, Blocks.log, 8, 1, 4, 5, boundingBox);
        this.placeBlockAtCurrentPosition(world, Blocks.log, 8, 15, 4, 5, boundingBox);
        //cobble walls
        this.fillWithBlocks(world, boundingBox, 2, 2, 1, 7, 2, 1, Blocks.cobblestone, Blocks.cobblestone, false);
        this.fillWithBlocks(world, boundingBox, 9, 2, 1, 14, 2, 1, Blocks.cobblestone, Blocks.cobblestone, false);
        this.fillWithBlocks(world, boundingBox, 1, 2, 2, 1, 2, 3, Blocks.cobblestone, Blocks.cobblestone, false);
        this.fillWithBlocks(world, boundingBox, 1, 2, 7, 1, 2, 8, Blocks.cobblestone, Blocks.cobblestone, false);
        this.fillWithBlocks(world, boundingBox, 15, 2, 2, 15, 2, 3, Blocks.cobblestone, Blocks.cobblestone, false);
        this.fillWithBlocks(world, boundingBox, 15, 2, 7, 15, 2, 8, Blocks.cobblestone, Blocks.cobblestone, false);
        this.fillWithBlocks(world, boundingBox, 2, 2, 9, 7, 2, 9, Blocks.cobblestone, Blocks.cobblestone, false);
        this.fillWithBlocks(world, boundingBox, 9, 2, 9, 14, 2, 9, Blocks.cobblestone, Blocks.cobblestone, false);
        //place glass
        this.fillWithBlocks(world, boundingBox, 1, 3, 2, 1, 5, 3, Blocks.glass, Blocks.glass, false);
        this.fillWithBlocks(world, boundingBox, 1, 3, 7, 1, 5, 8, Blocks.glass, Blocks.glass, false);
        this.fillWithBlocks(world, boundingBox, 15, 3, 2, 15, 5, 3, Blocks.glass, Blocks.glass, false);
        this.fillWithBlocks(world, boundingBox, 15, 3, 7, 15, 5, 8, Blocks.glass, Blocks.glass, false);
        this.fillWithBlocks(world, boundingBox, 2, 3, 1, 7, 5, 1, Blocks.glass, Blocks.glass, false);
        this.fillWithBlocks(world, boundingBox, 9, 3, 1, 14, 5, 1, Blocks.glass, Blocks.glass, false);
        this.fillWithBlocks(world, boundingBox, 2, 3, 9, 7, 5, 9, Blocks.glass, Blocks.glass, false);
        this.fillWithBlocks(world, boundingBox, 9, 3, 9, 14, 5, 9, Blocks.glass, Blocks.glass, false);
        this.fillWithBlocks(world, boundingBox, 2, 6, 2, 7, 6, 8, Blocks.glass, Blocks.glass, false);
        this.fillWithBlocks(world, boundingBox, 9, 6, 2, 14, 6, 8, Blocks.glass, Blocks.glass, false);
        this.placeBlockAtCurrentPosition(world, Blocks.glass, 0, 1, 5, 5, boundingBox);
        this.placeBlockAtCurrentPosition(world, Blocks.glass, 0, 15, 5, 5, boundingBox);
        //place doors
        this.placeBlockAtCurrentPosition(world, Blocks.wooden_door, 0, 1, 2, 5, boundingBox);
        this.placeBlockAtCurrentPosition(world, Blocks.wooden_door, 8, 1, 3, 5, boundingBox);
        this.placeBlockAtCurrentPosition(world, Blocks.wooden_door, 2, 15, 2, 5, boundingBox);
        this.placeBlockAtCurrentPosition(world, Blocks.wooden_door, 8, 15, 3, 5, boundingBox);
        //place air blocks
        this.fillWithBlocks(world, boundingBox, 0, 2, 0, 0, 9, 10, Blocks.air, Blocks.air, false);
        this.fillWithBlocks(world, boundingBox, 16, 2, 0, 16, 9, 10, Blocks.air, Blocks.air, false);
        this.fillWithBlocks(world, boundingBox, 0, 2, 0, 16, 9, 0, Blocks.air, Blocks.air, false);
        this.fillWithBlocks(world, boundingBox, 0, 2, 10, 16, 9, 10, Blocks.air, Blocks.air, false);
        this.fillWithBlocks(world, boundingBox, 2, 2, 2, 14, 5, 8, Blocks.air, Blocks.air, false);
        this.fillWithBlocks(world, boundingBox, 1, 7, 1, 14, 9, 8, Blocks.air, Blocks.air, false);
        //place torches
        this.placeBlockAtCurrentPosition(world, Blocks.torch, 0, 0, 4, 1, boundingBox);
        this.placeBlockAtCurrentPosition(world, Blocks.torch, 0, 0, 4, 4, boundingBox);
        this.placeBlockAtCurrentPosition(world, Blocks.torch, 0, 0, 4, 6, boundingBox);
        this.placeBlockAtCurrentPosition(world, Blocks.torch, 0, 0, 4, 9, boundingBox);
        this.placeBlockAtCurrentPosition(world, Blocks.torch, 0, 14, 4, 4, boundingBox);
        this.placeBlockAtCurrentPosition(world, Blocks.torch, 0, 14, 4, 6, boundingBox);
        this.placeBlockAtCurrentPosition(world, Blocks.torch, 0, 1, 4, 0, boundingBox);
        this.placeBlockAtCurrentPosition(world, Blocks.torch, 0, 8, 4, 0, boundingBox);
        this.placeBlockAtCurrentPosition(world, Blocks.torch, 0, 15, 4, 0, boundingBox);
        this.placeBlockAtCurrentPosition(world, Blocks.torch, 0, 8, 4, 8, boundingBox);
        this.placeBlockAtCurrentPosition(world, Blocks.torch, 0, 16, 4, 1, boundingBox);
        this.placeBlockAtCurrentPosition(world, Blocks.torch, 0, 16, 4, 4, boundingBox);
        this.placeBlockAtCurrentPosition(world, Blocks.torch, 0, 16, 4, 6, boundingBox);
        this.placeBlockAtCurrentPosition(world, Blocks.torch, 0, 16, 4, 9, boundingBox);
        this.placeBlockAtCurrentPosition(world, Blocks.torch, 0, 2, 4, 4, boundingBox);
        this.placeBlockAtCurrentPosition(world, Blocks.torch, 0, 2, 4, 6, boundingBox);
        this.placeBlockAtCurrentPosition(world, Blocks.torch, 0, 1, 4, 10, boundingBox);
        this.placeBlockAtCurrentPosition(world, Blocks.torch, 0, 8, 4, 10, boundingBox);
        this.placeBlockAtCurrentPosition(world, Blocks.torch, 0, 15, 4, 10, boundingBox);
        this.placeBlockAtCurrentPosition(world, Blocks.torch, 0, 8, 4, 2, boundingBox);
        //place crops
        for(int x=3;x<=7;x++) {
            for(int z=3;z<=7;z++) {
                this.generateStructureCrop(world, boundingBox, x, 2, z, (z%2==0 && x%2==0) || (x==5 &&z==5));
            }
        }
        for(int x=9;x<=13;x++) {
            for(int z=3;z<=7;z++) {
                this.generateStructureCrop(world, boundingBox, x, 2, z, (z%2==0 && x%2==0) || (x==11 &&z==5));
            }
        }
        this.spawnVillagers(world, boundingBox, 3, 1, 3, 1);
        return true;
    }

    //get random loot
    protected WeightedRandomChestContent[] getLoot() {
        int size = (int) Math.ceil(Math.random()*10);
        WeightedRandomChestContent[] loot = new WeightedRandomChestContent[size];
        for(int i=0;i<size;i++) {
            ItemStack seed = SeedHelper.getRandomSeed(true);
            loot[i] = new WeightedRandomChestContent(seed.getItem(), seed.getItemDamage(), 1, 3, 85);
        }
        return loot;
    }

    //place a crop
    protected boolean generateStructureCrop(World world, StructureBoundingBox boundingBox, int x, int y, int z, boolean crosscrop) {
        int xCoord = this.getXWithOffset(x, z);
        int yCoord = this.getYWithOffset(y);
        int zCoord = this.getZWithOffset(x, z);
        LogHelper.debug("Placing crop at ("+xCoord+","+yCoord+","+zCoord+")");
        if (boundingBox.isVecInside(xCoord, yCoord, zCoord)) {
            world.setBlock(xCoord, yCoord, zCoord, com.InfinityRaider.AgriCraft.init.Blocks.blockCrop, 0, 2);
            TileEntityCrop crop = (TileEntityCrop) world.getTileEntity(xCoord, yCoord, zCoord);
            if (crop!=null) {
                if(crosscrop && !ConfigurationHandler.enableWeeds) {
                    crop.setCrossCrop(true);
                }
                else {
                    ItemStack seed = SeedHelper.getRandomSeed(false);
                    crop.setPlant((int) Math.ceil(Math.random()*7), (int) Math.ceil(Math.random()*7), (int) Math.ceil(Math.random()*7), false, (ItemSeeds) seed.getItem(), seed.getItemDamage());
                }
            }
            return true;
        }
        else {
            return false;
        }
    }

    //place a seed analyzer
    protected boolean generateStructureSeedAnalyzer(World world, StructureBoundingBox boundingBox, int x, int y, int z, ForgeDirection direction) {
        int xCoord = this.getXWithOffset(x, z);
        int yCoord = this.getYWithOffset(y);
        int zCoord = this.getZWithOffset(x, z);
        if (boundingBox.isVecInside(xCoord, yCoord, zCoord)) {
            world.setBlock(xCoord, yCoord, zCoord, com.InfinityRaider.AgriCraft.init.Blocks.seedAnalyzer, 0, 2);
            TileEntitySeedAnalyzer analyzer = (TileEntitySeedAnalyzer) world.getTileEntity(xCoord, yCoord, zCoord);
            if (analyzer!=null) {
                if(direction!=null) {
                    analyzer.setDirection(direction.ordinal());
                }
            }
            return true;
        }
        else {
            return false;
        }
    }

    @Override
    protected int getVillagerType (int par1) {
        return ConfigurationHandler.villagerEnabled ? ConfigurationHandler.villagerID : 0;
    }
}