package com.InfinityRaider.AgriCraft.world;

import java.util.List;
import java.util.Random;

import com.InfinityRaider.AgriCraft.reference.Names;
import com.InfinityRaider.AgriCraft.tileentity.TileEntitySeedAnalyzer;
import com.InfinityRaider.AgriCraft.utility.SeedHelper;
import net.minecraft.init.Blocks;
import net.minecraft.item.ItemStack;
import net.minecraft.nbt.NBTTagCompound;
import net.minecraft.util.WeightedRandomChestContent;
import net.minecraft.world.World;
import net.minecraft.world.gen.structure.StructureBoundingBox;
import net.minecraft.world.gen.structure.StructureComponent;
import net.minecraft.world.gen.structure.StructureVillagePieces;
import net.minecraftforge.common.util.ForgeDirection;

public class StructureGreenhouse extends StructureVillagePieces.Village {
    //structure dimensions
    private static final int xSize = 17;
    private static final int ySize = 10;
    private static final int zSize = 16;
    //helper fields
    private int yOffset = -2;
    private boolean chestSpawned;

    public StructureGreenhouse(StructureVillagePieces.Start villagePiece, int nr, Random rand, StructureBoundingBox StructureBoundingBox, int coordBaseMode) {
        this.coordBaseMode = coordBaseMode;
        this.boundingBox = StructureBoundingBox;
    }

    //public method to build the component
    public static Object buildComponent(StructureVillagePieces.Start startPiece, List pieces, Random random, int p1, int p2, int p3, int p4, int p5) {
        StructureBoundingBox boundingBox = StructureBoundingBox.getComponentToAddBoundingBox(p1, p2, p3, 0, 0, 0, xSize, ySize, zSize, p4);
        return (canVillageGoDeeper(boundingBox)) && (StructureComponent.findIntersecting(pieces, boundingBox) == null)?new StructureGreenhouse(startPiece, p5, random, boundingBox, p4) : null;
    }

    //get random loot
    private WeightedRandomChestContent[] getLoot() {
        int size = (int) Math.ceil(Math.random()*10);
        WeightedRandomChestContent[] loot = new WeightedRandomChestContent[size];
        for(int i=0;i<size;i++) {
            ItemStack seed = SeedHelper.getRandomSeed();
            loot[i] = new WeightedRandomChestContent(seed.getItem(), seed.getItemDamage(), 1, 3, 85);
        }
        return loot;
    }

    //write to NBT
    @Override
    protected void func_143012_a(NBTTagCompound par1NBTTagCompound) {
        super.func_143012_a(par1NBTTagCompound);
        par1NBTTagCompound.setBoolean(Names.chestSpawned, this.chestSpawned);
    }

    //read from NBT
    @Override
    protected void func_143011_b(NBTTagCompound par1NBTTagCompound) {
        super.func_143011_b(par1NBTTagCompound);
        this.chestSpawned = par1NBTTagCompound.getBoolean(Names.chestSpawned);
    }

    //actually build the component
    @Override
    public boolean addComponentParts(World world, Random rand, StructureBoundingBox boundingBox) {
        if (this.yOffset < 0) {
            this.yOffset = getAverageGroundLevel(world, boundingBox);
            if (this.yOffset < 0) {
                return true;
            }
            this.boundingBox.offset(0, this.yOffset - this.boundingBox.maxY + 4, 0);
        }
        //structure generation code
        return true;
    }

//example code to figure out how to actually spawn shit in the world
/*
    public boolean addComponentParts(World world, Random random, StructureBoundingBox sbb) {
        if (this.averageGroundLevel < 0) {
            this.averageGroundLevel = getAverageGroundLevel(world, sbb);
            if (this.averageGroundLevel < 0) {
                return true;
            }
        this.boundingBox.offset(0, this.averageGroundLevel - this.boundingBox.maxY + 4, 0);
        }
        fillWithBlocks(world, sbb, 0, 2, 0, 6, 3, 6, Blocks.cobblestone, Blocks.cobblestone, false);
        fillWithBlocks(world, sbb, 0, 4, 0, 6, 7, 6, Blocks.planks, Blocks.planks, false);
        fillWithBlocks(world, sbb, 1, 2, 1, 5, 2, 5, Blocks.planks, Blocks.planks, false);
        fillWithAir(world, sbb, 1, 3, 1, 5, 5, 5);
        placeBlockAtCurrentPosition(world, Blocks.stone_stairs, getMetadataWithOffset(Blocks.stone_stairs, 3), 4, 2, -1, sbb);
        placeDoorAtCurrentPosition(world, sbb, random, 4, 3, 0, getMetadataWithOffset(Blocks.wooden_door, 3));
        for (int i = 0; i < 4; i++) {
            placeBlockAtCurrentPosition(world, Blocks.log, 0, 0, i + 2, 0, sbb);
            placeBlockAtCurrentPosition(world, Blocks.log, 0, 6, i + 2, 0, sbb);
            placeBlockAtCurrentPosition(world, Blocks.log, 0, 0, i + 2, 6, sbb);
            placeBlockAtCurrentPosition(world, Blocks.log, 0, 6, i + 2, 6, sbb);
            if ((i >= 1) && (i <= 4)) {
                placeBlockAtCurrentPosition(world, Blocks.log, 0, 3, i + 2, 1, sbb);
            }
        }
        for (int i = 0; i < 7; i++) {
            placeBlockAtCurrentPosition(world, Blocks.oak_stairs, getMetadataWithOffset(Blocks.oak_stairs, 3), i, 6, -1, sbb);
            placeBlockAtCurrentPosition(world, Blocks.oak_stairs, getMetadataWithOffset(Blocks.oak_stairs, 3), i, 7, 0, sbb);
        }
        for (int i = 0; i < 7; i++) {
            placeBlockAtCurrentPosition(world, Blocks.oak_stairs, getMetadataWithOffset(Blocks.oak_stairs, 2), i, 6, 7, sbb);
            placeBlockAtCurrentPosition(world, Blocks.oak_stairs, getMetadataWithOffset(Blocks.oak_stairs, 2), i, 7, 6, sbb);
        }
        fillWithBlocks(world, sbb, 1, 4, 0, 2, 5, 0, Blocks.glass_pane, Blocks.glass_pane, false);
        placeBlockAtCurrentPosition(world, Blocks.wool, 14, 1, 3, 1, sbb);
        placeBlockAtCurrentPosition(world, Blocks.wool, 14, 2, 3, 1, sbb);
        placeBlockAtCurrentPosition(world, Blocks.oak_stairs, getMetadataWithOffset(Blocks.oak_stairs, 2) + 4, 3, 5, 2, sbb);
        for (int i1 = 0; i1 < 2; i1++) {
            placeBlockAtCurrentPosition(world, Blocks.log, 0, i1 * 6, 4, 2, sbb);
            placeBlockAtCurrentPosition(world, Blocks.glass_pane, 0, i1 * 6, 4, 3, sbb);
            placeBlockAtCurrentPosition(world, Blocks.log, 0, i1 * 6, 4, 4, sbb);
        }
        placeBlockAtCurrentPosition(world, Blocks.planks, 1, 1, 3, 4, sbb);
        placeBlockAtCurrentPosition(world, Blocks.planks, 1, 2, 3, 4, sbb);
        placeBlockAtCurrentPosition(world, Blocks.planks, 1, 3, 3, 4, sbb);
        placeBlockAtCurrentPosition(world, Blocks.planks, 1, 3, 3, 5, sbb);
        for (int i2 = 1; i2 < 4; i2++) {
            placeBlockAtCurrentPosition(world, Blocks.wooden_slab, 1, i2, 5, 5, sbb);
        }
        placeBlockAtCurrentPosition(world, Blocks.torch, 0, 4, 5, 1, sbb);
        if (!this.hasMadeChest) {
            int i = getYWithOffset(1);
            int j = getXWithOffset(5, 5);
            int k = getZWithOffset(5, 5);
            if (sbb.isVecInside(j, i, k)) {
                this.hasMadeChest = true;
                generateStructureChestContents(world, sbb, random, 5, 3, 5, candleshopChest, 1 + random.nextInt(3));
            }
        } return true;
    }
*/

    //the actual structure
    private static void generateStructure(World world, int x, int y, int z) {
        world.setBlock(x, y + 2, z, Blocks.cobblestone, 0, 3);
        world.setBlock(x + 1, y + 2, z, Blocks.cobblestone, 0, 3);
        world.setBlock(x + 2, y + 2, z, Blocks.cobblestone, 0, 3);
        world.setBlock(x + 3, y + 2, z, Blocks.cobblestone, 0, 3);
        world.setBlock(x + 4, y + 2, z, Blocks.cobblestone, 0, 3);
        world.setBlock(x + 5, y + 2, z, Blocks.cobblestone, 0, 3);
        world.setBlock(x + 6, y + 2, z, Blocks.cobblestone, 0, 3);
        world.setBlock(x + 7, y + 2, z, Blocks.cobblestone, 0, 3);
        world.setBlock(x + 8, y + 2, z, Blocks.cobblestone, 0, 3);
        world.setBlock(x + 9, y + 2, z, Blocks.cobblestone, 0, 3);
        world.setBlock(x + 10, y + 2, z, Blocks.cobblestone, 0, 3);
        world.setBlock(x + 11, y + 2, z, Blocks.cobblestone, 0, 3);
        world.setBlock(x + 12, y + 2, z, Blocks.cobblestone, 0, 3);
        world.setBlock(x + 13, y + 2, z, Blocks.cobblestone, 0, 3);
        world.setBlock(x + 14, y + 2, z, Blocks.cobblestone, 0, 3);
        world.setBlock(x + 15, y + 2, z, Blocks.cobblestone, 0, 3);
        world.setBlock(x + 16, y + 2, z, Blocks.cobblestone, 0, 3);
        world.setBlock(x, y + 2, z + 1, Blocks.cobblestone, 0, 3);
        world.setBlock(x + 1, y + 2, z + 1, Blocks.cobblestone, 0, 3);
        world.setBlock(x + 2, y + 2, z + 1, Blocks.cobblestone, 0, 3);
        world.setBlock(x + 3, y + 2, z + 1, Blocks.cobblestone, 0, 3);
        world.setBlock(x + 4, y + 2, z + 1, Blocks.cobblestone, 0, 3);
        world.setBlock(x + 5, y + 2, z + 1, Blocks.cobblestone, 0, 3);
        world.setBlock(x + 6, y + 2, z + 1, Blocks.cobblestone, 0, 3);
        world.setBlock(x + 7, y + 2, z + 1, Blocks.cobblestone, 0, 3);
        world.setBlock(x + 8, y + 2, z + 1, Blocks.cobblestone, 0, 3);
        world.setBlock(x + 9, y + 2, z + 1, Blocks.cobblestone, 0, 3);
        world.setBlock(x + 10, y + 2, z + 1, Blocks.cobblestone, 0, 3);
        world.setBlock(x + 11, y + 2, z + 1, Blocks.cobblestone, 0, 3);
        world.setBlock(x + 12, y + 2, z + 1, Blocks.cobblestone, 0, 3);
        world.setBlock(x + 13, y + 2, z + 1, Blocks.cobblestone, 0, 3);
        world.setBlock(x + 14, y + 2, z + 1, Blocks.cobblestone, 0, 3);
        world.setBlock(x + 15, y + 2, z + 1, Blocks.cobblestone, 0, 3);
        world.setBlock(x + 16, y + 2, z + 1, Blocks.cobblestone, 0, 3);
        world.setBlock(x, y + 2, z + 2, Blocks.cobblestone, 0, 3);
        world.setBlock(x + 1, y + 2, z + 2, Blocks.cobblestone, 0, 3);
        world.setBlock(x + 2, y + 2, z + 2, Blocks.cobblestone, 0, 3);
        world.setBlock(x + 3, y + 2, z + 2, Blocks.cobblestone, 0, 3);
        world.setBlock(x + 4, y + 2, z + 2, Blocks.cobblestone, 0, 3);
        world.setBlock(x + 5, y + 2, z + 2, Blocks.cobblestone, 0, 3);
        world.setBlock(x + 6, y + 2, z + 2, Blocks.cobblestone, 0, 3);
        world.setBlock(x + 7, y + 2, z + 2, Blocks.cobblestone, 0, 3);
        world.setBlock(x + 8, y + 2, z + 2, Blocks.cobblestone, 0, 3);
        world.setBlock(x + 9, y + 2, z + 2, Blocks.cobblestone, 0, 3);
        world.setBlock(x + 10, y + 2, z + 2, Blocks.cobblestone, 0, 3);
        world.setBlock(x + 11, y + 2, z + 2, Blocks.cobblestone, 0, 3);
        world.setBlock(x + 12, y + 2, z + 2, Blocks.cobblestone, 0, 3);
        world.setBlock(x + 13, y + 2, z + 2, Blocks.cobblestone, 0, 3);
        world.setBlock(x + 14, y + 2, z + 2, Blocks.cobblestone, 0, 3);
        world.setBlock(x + 15, y + 2, z + 2, Blocks.cobblestone, 0, 3);
        world.setBlock(x + 16, y + 2, z + 2, Blocks.cobblestone, 0, 3);
        world.setBlock(x, y + 2, z + 3, Blocks.cobblestone, 0, 3);
        world.setBlock(x + 1, y + 2, z + 3, Blocks.cobblestone, 0, 3);
        world.setBlock(x + 2, y + 2, z + 3, Blocks.cobblestone, 0, 3);
        world.setBlock(x + 3, y + 2, z + 3, Blocks.cobblestone, 0, 3);
        world.setBlock(x + 4, y + 2, z + 3, Blocks.cobblestone, 0, 3);
        world.setBlock(x + 5, y + 2, z + 3, Blocks.cobblestone, 0, 3);
        world.setBlock(x + 6, y + 2, z + 3, Blocks.cobblestone, 0, 3);
        world.setBlock(x + 7, y + 2, z + 3, Blocks.cobblestone, 0, 3);
        world.setBlock(x + 8, y + 2, z + 3, Blocks.cobblestone, 0, 3);
        world.setBlock(x + 9, y + 2, z + 3, Blocks.cobblestone, 0, 3);
        world.setBlock(x + 10, y + 2, z + 3, Blocks.cobblestone, 0, 3);
        world.setBlock(x + 11, y + 2, z + 3, Blocks.cobblestone, 0, 3);
        world.setBlock(x + 12, y + 2, z + 3, Blocks.cobblestone, 0, 3);
        world.setBlock(x + 13, y + 2, z + 3, Blocks.cobblestone, 0, 3);
        world.setBlock(x + 14, y + 2, z + 3, Blocks.cobblestone, 0, 3);
        world.setBlock(x + 15, y + 2, z + 3, Blocks.cobblestone, 0, 3);
        world.setBlock(x + 16, y + 2, z + 3, Blocks.cobblestone, 0, 3);
        world.setBlock(x, y + 2, z + 4, Blocks.cobblestone, 0, 3);
        world.setBlock(x + 1, y + 2, z + 4, Blocks.cobblestone, 0, 3);
        world.setBlock(x + 2, y + 2, z + 4, Blocks.cobblestone, 0, 3);
        world.setBlock(x + 3, y + 2, z + 4, Blocks.cobblestone, 0, 3);
        world.setBlock(x + 4, y + 2, z + 4, Blocks.cobblestone, 0, 3);
        world.setBlock(x + 5, y + 2, z + 4, Blocks.cobblestone, 0, 3);
        world.setBlock(x + 6, y + 2, z + 4, Blocks.cobblestone, 0, 3);
        world.setBlock(x + 7, y + 2, z + 4, Blocks.cobblestone, 0, 3);
        world.setBlock(x + 8, y + 2, z + 4, Blocks.cobblestone, 0, 3);
        world.setBlock(x + 9, y + 2, z + 4, Blocks.cobblestone, 0, 3);
        world.setBlock(x + 10, y + 2, z + 4, Blocks.cobblestone, 0, 3);
        world.setBlock(x + 11, y + 2, z + 4, Blocks.cobblestone, 0, 3);
        world.setBlock(x + 12, y + 2, z + 4, Blocks.cobblestone, 0, 3);
        world.setBlock(x + 13, y + 2, z + 4, Blocks.cobblestone, 0, 3);
        world.setBlock(x + 14, y + 2, z + 4, Blocks.cobblestone, 0, 3);
        world.setBlock(x + 15, y + 2, z + 4, Blocks.cobblestone, 0, 3);
        world.setBlock(x + 16, y + 2, z + 4, Blocks.cobblestone, 0, 3);
        world.setBlock(x, y + 2, z + 5, Blocks.cobblestone, 0, 3);
        world.setBlock(x + 1, y + 2, z + 5, Blocks.cobblestone, 0, 3);
        world.setBlock(x + 2, y + 2, z + 5, Blocks.cobblestone, 0, 3);
        world.setBlock(x + 3, y + 2, z + 5, Blocks.cobblestone, 0, 3);
        world.setBlock(x + 4, y + 2, z + 5, Blocks.cobblestone, 0, 3);
        world.setBlock(x + 5, y + 2, z + 5, Blocks.cobblestone, 0, 3);
        world.setBlock(x + 6, y + 2, z + 5, Blocks.cobblestone, 0, 3);
        world.setBlock(x + 7, y + 2, z + 5, Blocks.cobblestone, 0, 3);
        world.setBlock(x + 8, y + 2, z + 5, Blocks.cobblestone, 0, 3);
        world.setBlock(x + 9, y + 2, z + 5, Blocks.cobblestone, 0, 3);
        world.setBlock(x + 10, y + 2, z + 5, Blocks.cobblestone, 0, 3);
        world.setBlock(x + 11, y + 2, z + 5, Blocks.cobblestone, 0, 3);
        world.setBlock(x + 12, y + 2, z + 5, Blocks.cobblestone, 0, 3);
        world.setBlock(x + 13, y + 2, z + 5, Blocks.cobblestone, 0, 3);
        world.setBlock(x + 14, y + 2, z + 5, Blocks.cobblestone, 0, 3);
        world.setBlock(x + 15, y + 2, z + 5, Blocks.cobblestone, 0, 3);
        world.setBlock(x + 16, y + 2, z + 5, Blocks.cobblestone, 0, 3);
        world.setBlock(x, y + 2, z + 6, Blocks.cobblestone, 0, 3);
        world.setBlock(x + 1, y + 2, z + 6, Blocks.cobblestone, 0, 3);
        world.setBlock(x + 2, y + 2, z + 6, Blocks.cobblestone, 0, 3);
        world.setBlock(x + 3, y + 2, z + 6, Blocks.cobblestone, 0, 3);
        world.setBlock(x + 4, y + 2, z + 6, Blocks.cobblestone, 0, 3);
        world.setBlock(x + 5, y + 2, z + 6, Blocks.cobblestone, 0, 3);
        world.setBlock(x + 6, y + 2, z + 6, Blocks.cobblestone, 0, 3);
        world.setBlock(x + 7, y + 2, z + 6, Blocks.cobblestone, 0, 3);
        world.setBlock(x + 8, y + 2, z + 6, Blocks.cobblestone, 0, 3);
        world.setBlock(x + 9, y + 2, z + 6, Blocks.cobblestone, 0, 3);
        world.setBlock(x + 10, y + 2, z + 6, Blocks.cobblestone, 0, 3);
        world.setBlock(x + 11, y + 2, z + 6, Blocks.cobblestone, 0, 3);
        world.setBlock(x + 12, y + 2, z + 6, Blocks.cobblestone, 0, 3);
        world.setBlock(x + 13, y + 2, z + 6, Blocks.cobblestone, 0, 3);
        world.setBlock(x + 14, y + 2, z + 6, Blocks.cobblestone, 0, 3);
        world.setBlock(x + 15, y + 2, z + 6, Blocks.cobblestone, 0, 3);
        world.setBlock(x + 16, y + 2, z + 6, Blocks.cobblestone, 0, 3);
        world.setBlock(x, y + 2, z + 7, Blocks.cobblestone, 0, 3);
        world.setBlock(x + 1, y + 2, z + 7, Blocks.cobblestone, 0, 3);
        world.setBlock(x + 2, y + 2, z + 7, Blocks.cobblestone, 0, 3);
        world.setBlock(x + 3, y + 2, z + 7, Blocks.cobblestone, 0, 3);
        world.setBlock(x + 4, y + 2, z + 7, Blocks.cobblestone, 0, 3);
        world.setBlock(x + 5, y + 2, z + 7, Blocks.cobblestone, 0, 3);
        world.setBlock(x + 6, y + 2, z + 7, Blocks.cobblestone, 0, 3);
        world.setBlock(x + 7, y + 2, z + 7, Blocks.cobblestone, 0, 3);
        world.setBlock(x + 8, y + 2, z + 7, Blocks.cobblestone, 0, 3);
        world.setBlock(x + 9, y + 2, z + 7, Blocks.cobblestone, 0, 3);
        world.setBlock(x + 10, y + 2, z + 7, Blocks.cobblestone, 0, 3);
        world.setBlock(x + 11, y + 2, z + 7, Blocks.cobblestone, 0, 3);
        world.setBlock(x + 12, y + 2, z + 7, Blocks.cobblestone, 0, 3);
        world.setBlock(x + 13, y + 2, z + 7, Blocks.cobblestone, 0, 3);
        world.setBlock(x + 14, y + 2, z + 7, Blocks.cobblestone, 0, 3);
        world.setBlock(x + 15, y + 2, z + 7, Blocks.cobblestone, 0, 3);
        world.setBlock(x + 16, y + 2, z + 7, Blocks.cobblestone, 0, 3);
        world.setBlock(x, y + 2, z + 8, Blocks.cobblestone, 0, 3);
        world.setBlock(x + 1, y + 2, z + 8, Blocks.cobblestone, 0, 3);
        world.setBlock(x + 2, y + 2, z + 8, Blocks.cobblestone, 0, 3);
        world.setBlock(x + 3, y + 2, z + 8, Blocks.cobblestone, 0, 3);
        world.setBlock(x + 4, y + 2, z + 8, Blocks.cobblestone, 0, 3);
        world.setBlock(x + 5, y + 2, z + 8, Blocks.cobblestone, 0, 3);
        world.setBlock(x + 6, y + 2, z + 8, Blocks.cobblestone, 0, 3);
        world.setBlock(x + 7, y + 2, z + 8, Blocks.cobblestone, 0, 3);
        world.setBlock(x + 8, y + 2, z + 8, Blocks.cobblestone, 0, 3);
        world.setBlock(x + 9, y + 2, z + 8, Blocks.cobblestone, 0, 3);
        world.setBlock(x + 10, y + 2, z + 8, Blocks.cobblestone, 0, 3);
        world.setBlock(x + 11, y + 2, z + 8, Blocks.cobblestone, 0, 3);
        world.setBlock(x + 12, y + 2, z + 8, Blocks.cobblestone, 0, 3);
        world.setBlock(x + 13, y + 2, z + 8, Blocks.cobblestone, 0, 3);
        world.setBlock(x + 14, y + 2, z + 8, Blocks.cobblestone, 0, 3);
        world.setBlock(x + 15, y + 2, z + 8, Blocks.cobblestone, 0, 3);
        world.setBlock(x + 16, y + 2, z + 8, Blocks.cobblestone, 0, 3);
        world.setBlock(x, y + 2, z + 9, Blocks.cobblestone, 0, 3);
        world.setBlock(x + 1, y + 2, z + 9, Blocks.cobblestone, 0, 3);
        world.setBlock(x + 2, y + 2, z + 9, Blocks.cobblestone, 0, 3);
        world.setBlock(x + 3, y + 2, z + 9, Blocks.cobblestone, 0, 3);
        world.setBlock(x + 4, y + 2, z + 9, Blocks.cobblestone, 0, 3);
        world.setBlock(x + 5, y + 2, z + 9, Blocks.cobblestone, 0, 3);
        world.setBlock(x + 6, y + 2, z + 9, Blocks.cobblestone, 0, 3);
        world.setBlock(x + 7, y + 2, z + 9, Blocks.cobblestone, 0, 3);
        world.setBlock(x + 8, y + 2, z + 9, Blocks.cobblestone, 0, 3);
        world.setBlock(x + 9, y + 2, z + 9, Blocks.cobblestone, 0, 3);
        world.setBlock(x + 10, y + 2, z + 9, Blocks.cobblestone, 0, 3);
        world.setBlock(x + 11, y + 2, z + 9, Blocks.cobblestone, 0, 3);
        world.setBlock(x + 12, y + 2, z + 9, Blocks.cobblestone, 0, 3);
        world.setBlock(x + 13, y + 2, z + 9, Blocks.cobblestone, 0, 3);
        world.setBlock(x + 14, y + 2, z + 9, Blocks.cobblestone, 0, 3);
        world.setBlock(x + 15, y + 2, z + 9, Blocks.cobblestone, 0, 3);
        world.setBlock(x + 16, y + 2, z + 9, Blocks.cobblestone, 0, 3);
        world.setBlock(x, y + 2, z + 10, Blocks.cobblestone, 0, 3);
        world.setBlock(x + 1, y + 2, z + 10, Blocks.cobblestone, 0, 3);
        world.setBlock(x + 2, y + 2, z + 10, Blocks.cobblestone, 0, 3);
        world.setBlock(x + 3, y + 2, z + 10, Blocks.cobblestone, 0, 3);
        world.setBlock(x + 4, y + 2, z + 10, Blocks.cobblestone, 0, 3);
        world.setBlock(x + 5, y + 2, z + 10, Blocks.cobblestone, 0, 3);
        world.setBlock(x + 6, y + 2, z + 10, Blocks.cobblestone, 0, 3);
        world.setBlock(x + 7, y + 2, z + 10, Blocks.cobblestone, 0, 3);
        world.setBlock(x + 8, y + 2, z + 10, Blocks.cobblestone, 0, 3);
        world.setBlock(x + 9, y + 2, z + 10, Blocks.cobblestone, 0, 3);
        world.setBlock(x + 10, y + 2, z + 10, Blocks.cobblestone, 0, 3);
        world.setBlock(x + 11, y + 2, z + 10, Blocks.cobblestone, 0, 3);
        world.setBlock(x + 12, y + 2, z + 10, Blocks.cobblestone, 0, 3);
        world.setBlock(x + 13, y + 2, z + 10, Blocks.cobblestone, 0, 3);
        world.setBlock(x + 14, y + 2, z + 10, Blocks.cobblestone, 0, 3);
        world.setBlock(x + 15, y + 2, z + 10, Blocks.cobblestone, 0, 3);
        world.setBlock(x + 16, y + 2, z + 10, Blocks.cobblestone, 0, 3);
        world.setBlock(x, y + 2, z + 11, Blocks.cobblestone, 0, 3);
        world.setBlock(x + 1, y + 2, z + 11, Blocks.cobblestone, 0, 3);
        world.setBlock(x + 2, y + 2, z + 11, Blocks.cobblestone, 0, 3);
        world.setBlock(x + 3, y + 2, z + 11, Blocks.cobblestone, 0, 3);
        world.setBlock(x + 4, y + 2, z + 11, Blocks.cobblestone, 0, 3);
        world.setBlock(x + 5, y + 2, z + 11, Blocks.cobblestone, 0, 3);
        world.setBlock(x + 6, y + 2, z + 11, Blocks.cobblestone, 0, 3);
        world.setBlock(x + 7, y + 2, z + 11, Blocks.cobblestone, 0, 3);
        world.setBlock(x + 8, y + 2, z + 11, Blocks.cobblestone, 0, 3);
        world.setBlock(x + 9, y + 2, z + 11, Blocks.cobblestone, 0, 3);
        world.setBlock(x + 10, y + 2, z + 11, Blocks.cobblestone, 0, 3);
        world.setBlock(x + 11, y + 2, z + 11, Blocks.cobblestone, 0, 3);
        world.setBlock(x + 12, y + 2, z + 11, Blocks.cobblestone, 0, 3);
        world.setBlock(x + 13, y + 2, z + 11, Blocks.cobblestone, 0, 3);
        world.setBlock(x + 14, y + 2, z + 11, Blocks.cobblestone, 0, 3);
        world.setBlock(x + 15, y + 2, z + 11, Blocks.cobblestone, 0, 3);
        world.setBlock(x + 16, y + 2, z + 11, Blocks.cobblestone, 0, 3);
        world.setBlock(x, y + 2, z + 12, Blocks.cobblestone, 0, 3);
        world.setBlock(x + 1, y + 2, z + 12, Blocks.cobblestone, 0, 3);
        world.setBlock(x + 2, y + 2, z + 12, Blocks.cobblestone, 0, 3);
        world.setBlock(x + 3, y + 2, z + 12, Blocks.cobblestone, 0, 3);
        world.setBlock(x + 4, y + 2, z + 12, Blocks.cobblestone, 0, 3);
        world.setBlock(x + 5, y + 2, z + 12, Blocks.cobblestone, 0, 3);
        world.setBlock(x + 6, y + 2, z + 12, Blocks.cobblestone, 0, 3);
        world.setBlock(x + 7, y + 2, z + 12, Blocks.cobblestone, 0, 3);
        world.setBlock(x + 8, y + 2, z + 12, Blocks.cobblestone, 0, 3);
        world.setBlock(x + 9, y + 2, z + 12, Blocks.cobblestone, 0, 3);
        world.setBlock(x + 10, y + 2, z + 12, Blocks.cobblestone, 0, 3);
        world.setBlock(x + 11, y + 2, z + 12, Blocks.cobblestone, 0, 3);
        world.setBlock(x + 12, y + 2, z + 12, Blocks.cobblestone, 0, 3);
        world.setBlock(x + 13, y + 2, z + 12, Blocks.cobblestone, 0, 3);
        world.setBlock(x + 14, y + 2, z + 12, Blocks.cobblestone, 0, 3);
        world.setBlock(x + 15, y + 2, z + 12, Blocks.cobblestone, 0, 3);
        world.setBlock(x + 16, y + 2, z + 12, Blocks.cobblestone, 0, 3);
        world.setBlock(x, y + 2, z + 13, Blocks.cobblestone, 0, 3);
        world.setBlock(x + 1, y + 2, z + 13, Blocks.cobblestone, 0, 3);
        world.setBlock(x + 2, y + 2, z + 13, Blocks.cobblestone, 0, 3);
        world.setBlock(x + 3, y + 2, z + 13, Blocks.cobblestone, 0, 3);
        world.setBlock(x + 4, y + 2, z + 13, Blocks.cobblestone, 0, 3);
        world.setBlock(x + 5, y + 2, z + 13, Blocks.cobblestone, 0, 3);
        world.setBlock(x + 6, y + 2, z + 13, Blocks.cobblestone, 0, 3);
        world.setBlock(x + 7, y + 2, z + 13, Blocks.cobblestone, 0, 3);
        world.setBlock(x + 8, y + 2, z + 13, Blocks.cobblestone, 0, 3);
        world.setBlock(x + 9, y + 2, z + 13, Blocks.cobblestone, 0, 3);
        world.setBlock(x + 10, y + 2, z + 13, Blocks.cobblestone, 0, 3);
        world.setBlock(x + 11, y + 2, z + 13, Blocks.cobblestone, 0, 3);
        world.setBlock(x + 12, y + 2, z + 13, Blocks.cobblestone, 0, 3);
        world.setBlock(x + 13, y + 2, z + 13, Blocks.cobblestone, 0, 3);
        world.setBlock(x + 14, y + 2, z + 13, Blocks.cobblestone, 0, 3);
        world.setBlock(x + 15, y + 2, z + 13, Blocks.cobblestone, 0, 3);
        world.setBlock(x + 16, y + 2, z + 13, Blocks.cobblestone, 0, 3);
        world.setBlock(x, y + 2, z + 14, Blocks.cobblestone, 0, 3);
        world.setBlock(x + 1, y + 2, z + 14, Blocks.cobblestone, 0, 3);
        world.setBlock(x + 2, y + 2, z + 14, Blocks.cobblestone, 0, 3);
        world.setBlock(x + 3, y + 2, z + 14, Blocks.cobblestone, 0, 3);
        world.setBlock(x + 4, y + 2, z + 14, Blocks.cobblestone, 0, 3);
        world.setBlock(x + 5, y + 2, z + 14, Blocks.cobblestone, 0, 3);
        world.setBlock(x + 6, y + 2, z + 14, Blocks.cobblestone, 0, 3);
        world.setBlock(x + 7, y + 2, z + 14, Blocks.cobblestone, 0, 3);
        world.setBlock(x + 8, y + 2, z + 14, Blocks.cobblestone, 0, 3);
        world.setBlock(x + 9, y + 2, z + 14, Blocks.cobblestone, 0, 3);
        world.setBlock(x + 10, y + 2, z + 14, Blocks.cobblestone, 0, 3);
        world.setBlock(x + 11, y + 2, z + 14, Blocks.cobblestone, 0, 3);
        world.setBlock(x + 12, y + 2, z + 14, Blocks.cobblestone, 0, 3);
        world.setBlock(x + 13, y + 2, z + 14, Blocks.cobblestone, 0, 3);
        world.setBlock(x + 14, y + 2, z + 14, Blocks.cobblestone, 0, 3);
        world.setBlock(x + 15, y + 2, z + 14, Blocks.cobblestone, 0, 3);
        world.setBlock(x + 16, y + 2, z + 14, Blocks.cobblestone, 0, 3);
        world.setBlock(x, y + 2, z + 15, Blocks.cobblestone, 0, 3);
        world.setBlock(x + 1, y + 2, z + 15, Blocks.cobblestone, 0, 3);
        world.setBlock(x + 2, y + 2, z + 15, Blocks.cobblestone, 0, 3);
        world.setBlock(x + 3, y + 2, z + 15, Blocks.cobblestone, 0, 3);
        world.setBlock(x + 4, y + 2, z + 15, Blocks.cobblestone, 0, 3);
        world.setBlock(x + 5, y + 2, z + 15, Blocks.cobblestone, 0, 3);
        world.setBlock(x + 6, y + 2, z + 15, Blocks.cobblestone, 0, 3);
        world.setBlock(x + 7, y + 2, z + 15, Blocks.cobblestone, 0, 3);
        world.setBlock(x + 8, y + 2, z + 15, Blocks.cobblestone, 0, 3);
        world.setBlock(x + 9, y + 2, z + 15, Blocks.cobblestone, 0, 3);
        world.setBlock(x + 10, y + 2, z + 15, Blocks.cobblestone, 0, 3);
        world.setBlock(x + 11, y + 2, z + 15, Blocks.cobblestone, 0, 3);
        world.setBlock(x + 12, y + 2, z + 15, Blocks.cobblestone, 0, 3);
        world.setBlock(x + 13, y + 2, z + 15, Blocks.cobblestone, 0, 3);
        world.setBlock(x + 14, y + 2, z + 15, Blocks.cobblestone, 0, 3);
        world.setBlock(x + 15, y + 2, z + 15, Blocks.cobblestone, 0, 3);
        world.setBlock(x + 16, y + 2, z + 15, Blocks.cobblestone, 0, 3);
        world.setBlock(x, y + 3, z, Blocks.gravel, 0, 3);
        world.setBlock(x + 1, y + 3, z, Blocks.gravel, 0, 3);
        world.setBlock(x + 2, y + 3, z, Blocks.gravel, 0, 3);
        world.setBlock(x + 3, y + 3, z, Blocks.gravel, 0, 3);
        world.setBlock(x + 4, y + 3, z, Blocks.gravel, 0, 3);
        world.setBlock(x + 5, y + 3, z, Blocks.gravel, 0, 3);
        world.setBlock(x + 6, y + 3, z, Blocks.gravel, 0, 3);
        world.setBlock(x + 7, y + 3, z, Blocks.gravel, 0, 3);
        world.setBlock(x + 8, y + 3, z, Blocks.gravel, 0, 3);
        world.setBlock(x + 9, y + 3, z, Blocks.gravel, 0, 3);
        world.setBlock(x + 10, y + 3, z, Blocks.gravel, 0, 3);
        world.setBlock(x + 11, y + 3, z, Blocks.gravel, 0, 3);
        world.setBlock(x + 12, y + 3, z, Blocks.gravel, 0, 3);
        world.setBlock(x + 13, y + 3, z, Blocks.gravel, 0, 3);
        world.setBlock(x + 14, y + 3, z, Blocks.gravel, 0, 3);
        world.setBlock(x + 15, y + 3, z, Blocks.gravel, 0, 3);
        world.setBlock(x + 16, y + 3, z, Blocks.gravel, 0, 3);
        world.setBlock(x, y + 3, z + 1, Blocks.gravel, 0, 3);
        world.setBlock(x + 1, y + 3, z + 1, Blocks.grass, 0, 3);
        world.setBlock(x + 2, y + 3, z + 1, Blocks.grass, 0, 3);
        world.setBlock(x + 3, y + 3, z + 1, Blocks.dirt, 0, 3);
        world.setBlock(x + 4, y + 3, z + 1, Blocks.grass, 0, 3);
        world.setBlock(x + 5, y + 3, z + 1, Blocks.grass, 0, 3);
        world.setBlock(x + 6, y + 3, z + 1, Blocks.dirt, 0, 3);
        world.setBlock(x + 7, y + 3, z + 1, Blocks.grass, 0, 3);
        world.setBlock(x + 8, y + 3, z + 1, Blocks.grass, 0, 3);
        world.setBlock(x + 9, y + 3, z + 1, Blocks.grass, 0, 3);
        world.setBlock(x + 10, y + 3, z + 1, Blocks.grass, 0, 3);
        world.setBlock(x + 11, y + 3, z + 1, Blocks.grass, 0, 3);
        world.setBlock(x + 12, y + 3, z + 1, Blocks.grass, 0, 3);
        world.setBlock(x + 13, y + 3, z + 1, Blocks.grass, 0, 3);
        world.setBlock(x + 14, y + 3, z + 1, Blocks.grass, 0, 3);
        world.setBlock(x + 15, y + 3, z + 1, Blocks.grass, 0, 3);
        world.setBlock(x + 16, y + 3, z + 1, Blocks.gravel, 0, 3);
        world.setBlock(x, y + 3, z + 2, Blocks.gravel, 0, 3);
        world.setBlock(x + 1, y + 3, z + 2, Blocks.grass, 0, 3);
        world.setBlock(x + 2, y + 3, z + 2, Blocks.grass, 0, 3);
        world.setBlock(x + 3, y + 3, z + 2, Blocks.grass, 0, 3);
        world.setBlock(x + 4, y + 3, z + 2, Blocks.grass, 0, 3);
        world.setBlock(x + 5, y + 3, z + 2, Blocks.grass, 0, 3);
        world.setBlock(x + 6, y + 3, z + 2, Blocks.grass, 0, 3);
        world.setBlock(x + 7, y + 3, z + 2, Blocks.grass, 0, 3);
        world.setBlock(x + 8, y + 3, z + 2, Blocks.grass, 0, 3);
        world.setBlock(x + 9, y + 3, z + 2, Blocks.grass, 0, 3);
        world.setBlock(x + 10, y + 3, z + 2, Blocks.grass, 0, 3);
        world.setBlock(x + 11, y + 3, z + 2, Blocks.grass, 0, 3);
        world.setBlock(x + 12, y + 3, z + 2, Blocks.grass, 0, 3);
        world.setBlock(x + 13, y + 3, z + 2, Blocks.grass, 0, 3);
        world.setBlock(x + 14, y + 3, z + 2, Blocks.grass, 0, 3);
        world.setBlock(x + 15, y + 3, z + 2, Blocks.grass, 0, 3);
        world.setBlock(x + 16, y + 3, z + 2, Blocks.gravel, 0, 3);
        world.setBlock(x, y + 3, z + 3, Blocks.gravel, 0, 3);
        world.setBlock(x + 1, y + 3, z + 3, Blocks.grass, 0, 3);
        world.setBlock(x + 2, y + 3, z + 3, Blocks.grass, 0, 3);
        world.setBlock(x + 3, y + 3, z + 3, Blocks.grass, 0, 3);
        world.setBlock(x + 4, y + 3, z + 3, Blocks.grass, 0, 3);
        world.setBlock(x + 5, y + 3, z + 3, Blocks.grass, 0, 3);
        world.setBlock(x + 6, y + 3, z + 3, Blocks.grass, 0, 3);
        world.setBlock(x + 7, y + 3, z + 3, Blocks.grass, 0, 3);
        world.setBlock(x + 8, y + 3, z + 3, Blocks.grass, 0, 3);
        world.setBlock(x + 9, y + 3, z + 3, Blocks.grass, 0, 3);
        world.setBlock(x + 10, y + 3, z + 3, Blocks.cobblestone, 0, 3);
        world.setBlock(x + 11, y + 3, z + 3, Blocks.cobblestone, 0, 3);
        world.setBlock(x + 12, y + 3, z + 3, Blocks.cobblestone, 0, 3);
        world.setBlock(x + 13, y + 3, z + 3, Blocks.cobblestone, 0, 3);
        world.setBlock(x + 14, y + 3, z + 3, Blocks.grass, 0, 3);
        world.setBlock(x + 15, y + 3, z + 3, Blocks.grass, 0, 3);
        world.setBlock(x + 16, y + 3, z + 3, Blocks.gravel, 0, 3);
        world.setBlock(x, y + 3, z + 4, Blocks.gravel, 0, 3);
        world.setBlock(x + 1, y + 3, z + 4, Blocks.grass, 0, 3);
        world.setBlock(x + 2, y + 3, z + 4, Blocks.grass, 0, 3);
        world.setBlock(x + 3, y + 3, z + 4, Blocks.gravel, 0, 3);
        world.setBlock(x + 4, y + 3, z + 4, Blocks.grass, 0, 3);
        world.setBlock(x + 5, y + 3, z + 4, Blocks.grass, 0, 3);
        world.setBlock(x + 6, y + 3, z + 4, Blocks.gravel, 0, 3);
        world.setBlock(x + 7, y + 3, z + 4, Blocks.grass, 0, 3);
        world.setBlock(x + 8, y + 3, z + 4, Blocks.grass, 0, 3);
        world.setBlock(x + 9, y + 3, z + 4, Blocks.grass, 0, 3);
        world.setBlock(x + 10, y + 3, z + 4, Blocks.cobblestone, 0, 3);
        world.setBlock(x + 11, y + 3, z + 4, Blocks.double_stone_slab, 0, 3);
        world.setBlock(x + 12, y + 3, z + 4, Blocks.double_stone_slab, 0, 3);
        world.setBlock(x + 13, y + 3, z + 4, Blocks.cobblestone, 0, 3);
        world.setBlock(x + 14, y + 3, z + 4, Blocks.grass, 0, 3);
        world.setBlock(x + 15, y + 3, z + 4, Blocks.grass, 0, 3);
        world.setBlock(x + 16, y + 3, z + 4, Blocks.gravel, 0, 3);
        world.setBlock(x, y + 3, z + 5, Blocks.gravel, 0, 3);
        world.setBlock(x + 1, y + 3, z + 5, Blocks.grass, 0, 3);
        world.setBlock(x + 2, y + 3, z + 5, Blocks.grass, 0, 3);
        world.setBlock(x + 3, y + 3, z + 5, Blocks.grass, 0, 3);
        world.setBlock(x + 4, y + 3, z + 5, Blocks.grass, 0, 3);
        world.setBlock(x + 5, y + 3, z + 5, Blocks.grass, 0, 3);
        world.setBlock(x + 6, y + 3, z + 5, Blocks.grass, 0, 3);
        world.setBlock(x + 7, y + 3, z + 5, Blocks.grass, 0, 3);
        world.setBlock(x + 8, y + 3, z + 5, Blocks.grass, 0, 3);
        world.setBlock(x + 9, y + 3, z + 5, Blocks.grass, 0, 3);
        world.setBlock(x + 10, y + 3, z + 5, Blocks.cobblestone, 0, 3);
        world.setBlock(x + 11, y + 3, z + 5, Blocks.double_stone_slab, 0, 3);
        world.setBlock(x + 12, y + 3, z + 5, Blocks.double_stone_slab, 0, 3);
        world.setBlock(x + 13, y + 3, z + 5, Blocks.cobblestone, 0, 3);
        world.setBlock(x + 14, y + 3, z + 5, Blocks.grass, 0, 3);
        world.setBlock(x + 15, y + 3, z + 5, Blocks.grass, 0, 3);
        world.setBlock(x + 16, y + 3, z + 5, Blocks.gravel, 0, 3);
        world.setBlock(x, y + 3, z + 6, Blocks.gravel, 0, 3);
        world.setBlock(x + 1, y + 3, z + 6, Blocks.cobblestone, 0, 3);
        world.setBlock(x + 2, y + 3, z + 6, Blocks.water, 0, 3);
        world.setBlock(x + 3, y + 3, z + 6, Blocks.water, 0, 3);
        world.setBlock(x + 4, y + 3, z + 6, Blocks.water, 0, 3);
        world.setBlock(x + 5, y + 3, z + 6, Blocks.water, 0, 3);
        world.setBlock(x + 6, y + 3, z + 6, Blocks.water, 0, 3);
        world.setBlock(x + 7, y + 3, z + 6, Blocks.water, 0, 3);
        world.setBlock(x + 8, y + 3, z + 6, Blocks.water, 0, 3);
        world.setBlock(x + 9, y + 3, z + 6, Blocks.water, 0, 3);
        world.setBlock(x + 10, y + 3, z + 6, Blocks.water, 0, 3);
        world.setBlock(x + 11, y + 3, z + 6, Blocks.double_stone_slab, 0, 3);
        world.setBlock(x + 12, y + 3, z + 6, Blocks.double_stone_slab, 0, 3);
        world.setBlock(x + 13, y + 3, z + 6, Blocks.water, 0, 3);
        world.setBlock(x + 14, y + 3, z + 6, Blocks.water, 0, 3);
        world.setBlock(x + 15, y + 3, z + 6, Blocks.cobblestone, 0, 3);
        world.setBlock(x + 16, y + 3, z + 6, Blocks.gravel, 0, 3);
        world.setBlock(x, y + 3, z + 7, Blocks.gravel, 0, 3);
        world.setBlock(x + 1, y + 3, z + 7, Blocks.cobblestone, 0, 3);
        world.setBlock(x + 2, y + 3, z + 7, Blocks.double_stone_slab, 0, 3);
        world.setBlock(x + 3, y + 3, z + 7, Blocks.double_stone_slab, 0, 3);
        world.setBlock(x + 4, y + 3, z + 7, Blocks.double_stone_slab, 0, 3);
        world.setBlock(x + 5, y + 3, z + 7, Blocks.double_stone_slab, 0, 3);
        world.setBlock(x + 6, y + 3, z + 7, Blocks.double_stone_slab, 0, 3);
        world.setBlock(x + 7, y + 3, z + 7, Blocks.double_stone_slab, 0, 3);
        world.setBlock(x + 8, y + 3, z + 7, Blocks.double_stone_slab, 0, 3);
        world.setBlock(x + 9, y + 3, z + 7, Blocks.double_stone_slab, 0, 3);
        world.setBlock(x + 10, y + 3, z + 7, Blocks.double_stone_slab, 0, 3);
        world.setBlock(x + 11, y + 3, z + 7, Blocks.double_stone_slab, 0, 3);
        world.setBlock(x + 12, y + 3, z + 7, Blocks.double_stone_slab, 0, 3);
        world.setBlock(x + 13, y + 3, z + 7, Blocks.double_stone_slab, 0, 3);
        world.setBlock(x + 14, y + 3, z + 7, Blocks.double_stone_slab, 0, 3);
        world.setBlock(x + 15, y + 3, z + 7, Blocks.cobblestone, 0, 3);
        world.setBlock(x + 16, y + 3, z + 7, Blocks.gravel, 0, 3);
        world.setBlock(x, y + 3, z + 8, Blocks.gravel, 0, 3);
        world.setBlock(x + 1, y + 3, z + 8, Blocks.cobblestone, 0, 3);
        world.setBlock(x + 2, y + 3, z + 8, Blocks.double_stone_slab, 0, 3);
        world.setBlock(x + 3, y + 3, z + 8, Blocks.farmland, 7, 3);
        world.setBlock(x + 4, y + 3, z + 8, Blocks.farmland, 7, 3);
        world.setBlock(x + 5, y + 3, z + 8, Blocks.farmland, 7, 3);
        world.setBlock(x + 6, y + 3, z + 8, Blocks.farmland, 7, 3);
        world.setBlock(x + 7, y + 3, z + 8, Blocks.farmland, 7, 3);
        world.setBlock(x + 8, y + 3, z + 8, Blocks.double_stone_slab, 0, 3);
        world.setBlock(x + 9, y + 3, z + 8, Blocks.farmland, 7, 3);
        world.setBlock(x + 10, y + 3, z + 8, Blocks.farmland, 7, 3);
        world.setBlock(x + 11, y + 3, z + 8, Blocks.farmland, 7, 3);
        world.setBlock(x + 12, y + 3, z + 8, Blocks.farmland, 7, 3);
        world.setBlock(x + 13, y + 3, z + 8, Blocks.farmland, 7, 3);
        world.setBlock(x + 14, y + 3, z + 8, Blocks.double_stone_slab, 0, 3);
        world.setBlock(x + 15, y + 3, z + 8, Blocks.cobblestone, 0, 3);
        world.setBlock(x + 16, y + 3, z + 8, Blocks.gravel, 0, 3);
        world.setBlock(x, y + 3, z + 9, Blocks.gravel, 0, 3);
        world.setBlock(x + 1, y + 3, z + 9, Blocks.cobblestone, 0, 3);
        world.setBlock(x + 2, y + 3, z + 9, Blocks.double_stone_slab, 0, 3);
        world.setBlock(x + 3, y + 3, z + 9, Blocks.farmland, 7, 3);
        world.setBlock(x + 4, y + 3, z + 9, Blocks.farmland, 7, 3);
        world.setBlock(x + 5, y + 3, z + 9, Blocks.farmland, 7, 3);
        world.setBlock(x + 6, y + 3, z + 9, Blocks.farmland, 7, 3);
        world.setBlock(x + 7, y + 3, z + 9, Blocks.farmland, 7, 3);
        world.setBlock(x + 8, y + 3, z + 9, Blocks.double_stone_slab, 0, 3);
        world.setBlock(x + 9, y + 3, z + 9, Blocks.farmland, 7, 3);
        world.setBlock(x + 10, y + 3, z + 9, Blocks.farmland, 7, 3);
        world.setBlock(x + 11, y + 3, z + 9, Blocks.farmland, 7, 3);
        world.setBlock(x + 12, y + 3, z + 9, Blocks.farmland, 7, 3);
        world.setBlock(x + 13, y + 3, z + 9, Blocks.farmland, 7, 3);
        world.setBlock(x + 14, y + 3, z + 9, Blocks.double_stone_slab, 0, 3);
        world.setBlock(x + 15, y + 3, z + 9, Blocks.cobblestone, 0, 3);
        world.setBlock(x + 16, y + 3, z + 9, Blocks.gravel, 0, 3);
        world.setBlock(x, y + 3, z + 10, Blocks.gravel, 0, 3);
        world.setBlock(x + 1, y + 3, z + 10, Blocks.double_stone_slab, 0, 3);
        world.setBlock(x + 2, y + 3, z + 10, Blocks.double_stone_slab, 0, 3);
        world.setBlock(x + 3, y + 3, z + 10, Blocks.farmland, 7, 3);
        world.setBlock(x + 4, y + 3, z + 10, Blocks.farmland, 7, 3);
        world.setBlock(x + 5, y + 3, z + 10, Blocks.farmland, 7, 3);
        world.setBlock(x + 6, y + 3, z + 10, Blocks.farmland, 7, 3);
        world.setBlock(x + 7, y + 3, z + 10, Blocks.farmland, 7, 3);
        world.setBlock(x + 8, y + 3, z + 10, Blocks.double_stone_slab, 0, 3);
        world.setBlock(x + 9, y + 3, z + 10, Blocks.farmland, 7, 3);
        world.setBlock(x + 10, y + 3, z + 10, Blocks.farmland, 7, 3);
        world.setBlock(x + 11, y + 3, z + 10, Blocks.farmland, 7, 3);
        world.setBlock(x + 12, y + 3, z + 10, Blocks.farmland, 7, 3);
        world.setBlock(x + 13, y + 3, z + 10, Blocks.farmland, 7, 3);
        world.setBlock(x + 14, y + 3, z + 10, Blocks.double_stone_slab, 0, 3);
        world.setBlock(x + 15, y + 3, z + 10, Blocks.double_stone_slab, 0, 3);
        world.setBlock(x + 16, y + 3, z + 10, Blocks.gravel, 0, 3);
        world.setBlock(x, y + 3, z + 11, Blocks.gravel, 0, 3);
        world.setBlock(x + 1, y + 3, z + 11, Blocks.cobblestone, 0, 3);
        world.setBlock(x + 2, y + 3, z + 11, Blocks.double_stone_slab, 0, 3);
        world.setBlock(x + 3, y + 3, z + 11, Blocks.farmland, 7, 3);
        world.setBlock(x + 4, y + 3, z + 11, Blocks.farmland, 7, 3);
        world.setBlock(x + 5, y + 3, z + 11, Blocks.farmland, 7, 3);
        world.setBlock(x + 6, y + 3, z + 11, Blocks.farmland, 7, 3);
        world.setBlock(x + 7, y + 3, z + 11, Blocks.farmland, 7, 3);
        world.setBlock(x + 8, y + 3, z + 11, Blocks.double_stone_slab, 0, 3);
        world.setBlock(x + 9, y + 3, z + 11, Blocks.farmland, 7, 3);
        world.setBlock(x + 10, y + 3, z + 11, Blocks.farmland, 7, 3);
        world.setBlock(x + 11, y + 3, z + 11, Blocks.farmland, 7, 3);
        world.setBlock(x + 12, y + 3, z + 11, Blocks.farmland, 7, 3);
        world.setBlock(x + 13, y + 3, z + 11, Blocks.farmland, 7, 3);
        world.setBlock(x + 14, y + 3, z + 11, Blocks.double_stone_slab, 0, 3);
        world.setBlock(x + 15, y + 3, z + 11, Blocks.cobblestone, 0, 3);
        world.setBlock(x + 16, y + 3, z + 11, Blocks.gravel, 0, 3);
        world.setBlock(x, y + 3, z + 12, Blocks.gravel, 0, 3);
        world.setBlock(x + 1, y + 3, z + 12, Blocks.cobblestone, 0, 3);
        world.setBlock(x + 2, y + 3, z + 12, Blocks.double_stone_slab, 0, 3);
        world.setBlock(x + 3, y + 3, z + 12, Blocks.farmland, 7, 3);
        world.setBlock(x + 4, y + 3, z + 12, Blocks.farmland, 7, 3);
        world.setBlock(x + 5, y + 3, z + 12, Blocks.farmland, 7, 3);
        world.setBlock(x + 6, y + 3, z + 12, Blocks.farmland, 7, 3);
        world.setBlock(x + 7, y + 3, z + 12, Blocks.farmland, 7, 3);
        world.setBlock(x + 8, y + 3, z + 12, Blocks.double_stone_slab, 0, 3);
        world.setBlock(x + 9, y + 3, z + 12, Blocks.farmland, 7, 3);
        world.setBlock(x + 10, y + 3, z + 12, Blocks.farmland, 7, 3);
        world.setBlock(x + 11, y + 3, z + 12, Blocks.farmland, 7, 3);
        world.setBlock(x + 12, y + 3, z + 12, Blocks.farmland, 7, 3);
        world.setBlock(x + 13, y + 3, z + 12, Blocks.farmland, 7, 3);
        world.setBlock(x + 14, y + 3, z + 12, Blocks.double_stone_slab, 0, 3);
        world.setBlock(x + 15, y + 3, z + 12, Blocks.cobblestone, 0, 3);
        world.setBlock(x + 16, y + 3, z + 12, Blocks.gravel, 0, 3);
        world.setBlock(x, y + 3, z + 13, Blocks.gravel, 0, 3);
        world.setBlock(x + 1, y + 3, z + 13, Blocks.cobblestone, 0, 3);
        world.setBlock(x + 2, y + 3, z + 13, Blocks.double_stone_slab, 0, 3);
        world.setBlock(x + 3, y + 3, z + 13, Blocks.double_stone_slab, 0, 3);
        world.setBlock(x + 4, y + 3, z + 13, Blocks.double_stone_slab, 0, 3);
        world.setBlock(x + 5, y + 3, z + 13, Blocks.double_stone_slab, 0, 3);
        world.setBlock(x + 6, y + 3, z + 13, Blocks.double_stone_slab, 0, 3);
        world.setBlock(x + 7, y + 3, z + 13, Blocks.double_stone_slab, 0, 3);
        world.setBlock(x + 8, y + 3, z + 13, Blocks.double_stone_slab, 0, 3);
        world.setBlock(x + 9, y + 3, z + 13, Blocks.double_stone_slab, 0, 3);
        world.setBlock(x + 10, y + 3, z + 13, Blocks.double_stone_slab, 0, 3);
        world.setBlock(x + 11, y + 3, z + 13, Blocks.double_stone_slab, 0, 3);
        world.setBlock(x + 12, y + 3, z + 13, Blocks.double_stone_slab, 0, 3);
        world.setBlock(x + 13, y + 3, z + 13, Blocks.double_stone_slab, 0, 3);
        world.setBlock(x + 14, y + 3, z + 13, Blocks.double_stone_slab, 0, 3);
        world.setBlock(x + 15, y + 3, z + 13, Blocks.cobblestone, 0, 3);
        world.setBlock(x + 16, y + 3, z + 13, Blocks.gravel, 0, 3);
        world.setBlock(x, y + 3, z + 14, Blocks.gravel, 0, 3);
        world.setBlock(x + 1, y + 3, z + 14, Blocks.cobblestone, 0, 3);
        world.setBlock(x + 2, y + 3, z + 14, Blocks.water, 0, 3);
        world.setBlock(x + 3, y + 3, z + 14, Blocks.water, 0, 3);
        world.setBlock(x + 4, y + 3, z + 14, Blocks.water, 0, 3);
        world.setBlock(x + 5, y + 3, z + 14, Blocks.water, 0, 3);
        world.setBlock(x + 6, y + 3, z + 14, Blocks.water, 0, 3);
        world.setBlock(x + 7, y + 3, z + 14, Blocks.water, 0, 3);
        world.setBlock(x + 8, y + 3, z + 14, Blocks.water, 0, 3);
        world.setBlock(x + 9, y + 3, z + 14, Blocks.water, 0, 3);
        world.setBlock(x + 10, y + 3, z + 14, Blocks.water, 0, 3);
        world.setBlock(x + 11, y + 3, z + 14, Blocks.water, 0, 3);
        world.setBlock(x + 12, y + 3, z + 14, Blocks.water, 0, 3);
        world.setBlock(x + 13, y + 3, z + 14, Blocks.water, 0, 3);
        world.setBlock(x + 14, y + 3, z + 14, Blocks.water, 0, 3);
        world.setBlock(x + 15, y + 3, z + 14, Blocks.cobblestone, 0, 3);
        world.setBlock(x + 16, y + 3, z + 14, Blocks.gravel, 0, 3);
        world.setBlock(x, y + 3, z + 15, Blocks.gravel, 0, 3);
        world.setBlock(x + 1, y + 3, z + 15, Blocks.gravel, 0, 3);
        world.setBlock(x + 2, y + 3, z + 15, Blocks.gravel, 0, 3);
        world.setBlock(x + 3, y + 3, z + 15, Blocks.gravel, 0, 3);
        world.setBlock(x + 4, y + 3, z + 15, Blocks.gravel, 0, 3);
        world.setBlock(x + 5, y + 3, z + 15, Blocks.gravel, 0, 3);
        world.setBlock(x + 6, y + 3, z + 15, Blocks.gravel, 0, 3);
        world.setBlock(x + 7, y + 3, z + 15, Blocks.gravel, 0, 3);
        world.setBlock(x + 8, y + 3, z + 15, Blocks.gravel, 0, 3);
        world.setBlock(x + 9, y + 3, z + 15, Blocks.gravel, 0, 3);
        world.setBlock(x + 10, y + 3, z + 15, Blocks.gravel, 0, 3);
        world.setBlock(x + 11, y + 3, z + 15, Blocks.gravel, 0, 3);
        world.setBlock(x + 12, y + 3, z + 15, Blocks.gravel, 0, 3);
        world.setBlock(x + 13, y + 3, z + 15, Blocks.gravel, 0, 3);
        world.setBlock(x + 14, y + 3, z + 15, Blocks.gravel, 0, 3);
        world.setBlock(x + 15, y + 3, z + 15, Blocks.gravel, 0, 3);
        world.setBlock(x + 16, y + 3, z + 15, Blocks.gravel, 0, 3);
        world.setBlock(x, y + 4, z, Blocks.air, 0, 3);
        world.setBlock(x + 1, y + 4, z, Blocks.air, 0, 3);
        world.setBlock(x + 2, y + 4, z, Blocks.air, 0, 3);
        world.setBlock(x + 3, y + 4, z, Blocks.air, 0, 3);
        world.setBlock(x + 4, y + 4, z, Blocks.air, 0, 3);
        world.setBlock(x + 5, y + 4, z, Blocks.air, 0, 3);
        world.setBlock(x + 6, y + 4, z, Blocks.air, 0, 3);
        world.setBlock(x + 7, y + 4, z, Blocks.air, 0, 3);
        world.setBlock(x + 8, y + 4, z, Blocks.air, 0, 3);
        world.setBlock(x + 9, y + 4, z, Blocks.air, 0, 3);
        world.setBlock(x + 10, y + 4, z, Blocks.air, 0, 3);
        world.setBlock(x + 11, y + 4, z, Blocks.air, 0, 3);
        world.setBlock(x + 12, y + 4, z, Blocks.air, 0, 3);
        world.setBlock(x + 13, y + 4, z, Blocks.air, 0, 3);
        world.setBlock(x + 14, y + 4, z, Blocks.air, 0, 3);
        world.setBlock(x + 15, y + 4, z, Blocks.air, 0, 3);
        world.setBlock(x + 16, y + 4, z, Blocks.air, 0, 3);
        world.setBlock(x, y + 4, z + 1, Blocks.air, 0, 3);
        world.setBlock(x + 1, y + 4, z + 1, Blocks.fence, 0, 3);
        world.setBlock(x + 2, y + 4, z + 1, Blocks.fence, 0, 3);
        world.setBlock(x + 3, y + 4, z + 1, Blocks.planks, 0, 3);
        world.setBlock(x + 4, y + 4, z + 1, Blocks.fence, 0, 3);
        world.setBlock(x + 5, y + 4, z + 1, Blocks.fence, 0, 3);
        world.setBlock(x + 6, y + 4, z + 1, Blocks.planks, 0, 3);
        world.setBlock(x + 7, y + 4, z + 1, Blocks.fence, 0, 3);
        world.setBlock(x + 8, y + 4, z + 1, Blocks.fence, 0, 3);
        world.setBlock(x + 9, y + 4, z + 1, Blocks.fence, 0, 3);
        world.setBlock(x + 10, y + 4, z + 1, Blocks.fence, 0, 3);
        world.setBlock(x + 11, y + 4, z + 1, Blocks.fence, 0, 3);
        world.setBlock(x + 12, y + 4, z + 1, Blocks.fence, 0, 3);
        world.setBlock(x + 13, y + 4, z + 1, Blocks.fence, 0, 3);
        world.setBlock(x + 14, y + 4, z + 1, Blocks.fence, 0, 3);
        world.setBlock(x + 15, y + 4, z + 1, Blocks.fence, 0, 3);
        world.setBlock(x + 16, y + 4, z + 1, Blocks.air, 0, 3);
        world.setBlock(x, y + 4, z + 2, Blocks.air, 0, 3);
        world.setBlock(x + 1, y + 4, z + 2, Blocks.fence, 0, 3);
        world.setBlock(x + 2, y + 4, z + 2, Blocks.air, 0, 3);
        world.setBlock(x + 3, y + 4, z + 2, Blocks.air, 0, 3);
        world.setBlock(x + 4, y + 4, z + 2, Blocks.air, 0, 3);
        world.setBlock(x + 5, y + 4, z + 2, Blocks.air, 0, 3);
        world.setBlock(x + 6, y + 4, z + 2, Blocks.air, 0, 3);
        world.setBlock(x + 7, y + 4, z + 2, Blocks.red_flower, 6, 3);
        world.setBlock(x + 8, y + 4, z + 2, Blocks.red_flower, 2, 3);
        world.setBlock(x + 9, y + 4, z + 2, Blocks.red_flower, 3, 3);
        world.setBlock(x + 10, y + 4, z + 2, Blocks.red_flower, 0, 3);
        world.setBlock(x + 11, y + 4, z + 2, Blocks.red_flower, 5, 3);
        world.setBlock(x + 12, y + 4, z + 2, Blocks.red_flower, 2, 3);
        world.setBlock(x + 13, y + 4, z + 2, Blocks.yellow_flower, 0, 3);
        world.setBlock(x + 14, y + 4, z + 2, Blocks.red_flower, 1, 3);
        world.setBlock(x + 15, y + 4, z + 2, Blocks.fence, 0, 3);
        world.setBlock(x + 16, y + 4, z + 2, Blocks.air, 0, 3);
        world.setBlock(x, y + 4, z + 3, Blocks.air, 0, 3);
        world.setBlock(x + 1, y + 4, z + 3, Blocks.fence, 0, 3);
        world.setBlock(x + 2, y + 4, z + 3, Blocks.air, 0, 3);
        world.setBlock(x + 3, y + 4, z + 3, Blocks.air, 0, 3);
        world.setBlock(x + 4, y + 4, z + 3, Blocks.air, 0, 3);
        world.setBlock(x + 5, y + 4, z + 3, Blocks.air, 0, 3);
        world.setBlock(x + 6, y + 4, z + 3, Blocks.air, 0, 3);
        world.setBlock(x + 7, y + 4, z + 3, Blocks.red_flower, 1, 3);
        world.setBlock(x + 8, y + 4, z + 3, Blocks.yellow_flower, 0, 3);
        world.setBlock(x + 9, y + 4, z + 3, Blocks.red_flower, 5, 3);
        world.setBlock(x + 10, y + 4, z + 3, Blocks.log, 0, 3);
        world.setBlock(x + 11, y + 4, z + 3, Blocks.cobblestone, 0, 3);
        world.setBlock(x + 12, y + 4, z + 3, Blocks.cobblestone, 0, 3);
        world.setBlock(x + 13, y + 4, z + 3, Blocks.log, 0, 3);
        world.setBlock(x + 14, y + 4, z + 3, Blocks.red_flower, 4, 3);
        world.setBlock(x + 15, y + 4, z + 3, Blocks.fence, 0, 3);
        world.setBlock(x + 16, y + 4, z + 3, Blocks.air, 0, 3);
        world.setBlock(x, y + 4, z + 4, Blocks.air, 0, 3);
        world.setBlock(x + 1, y + 4, z + 4, Blocks.fence, 0, 3);
        world.setBlock(x + 2, y + 4, z + 4, Blocks.air, 0, 3);
        world.setBlock(x + 3, y + 4, z + 4, Blocks.planks, 0, 3);
        world.setBlock(x + 4, y + 4, z + 4, Blocks.air, 0, 3);
        world.setBlock(x + 5, y + 4, z + 4, Blocks.air, 0, 3);
        world.setBlock(x + 6, y + 4, z + 4, Blocks.planks, 0, 3);
        world.setBlock(x + 7, y + 4, z + 4, Blocks.air, 0, 3);
        world.setBlock(x + 8, y + 4, z + 4, Blocks.red_flower, 4, 3);
        world.setBlock(x + 9, y + 4, z + 4, Blocks.air, 0, 3);
        world.setBlock(x + 10, y + 4, z + 4, Blocks.cobblestone, 0, 3);
        world.setBlock(x + 11, y + 4, z + 4, com.InfinityRaider.AgriCraft.init.Blocks.seedAnalyzer, 0, 3);
        ((TileEntitySeedAnalyzer) world.getTileEntity(x + 11, y + 4, z + 4)).setDirection(ForgeDirection.SOUTH.ordinal());
        world.setBlock(x + 12, y + 4, z + 4, Blocks.chest, 3, 3);
        world.setBlock(x + 13, y + 4, z + 4, Blocks.cobblestone, 0, 3);
        world.setBlock(x + 14, y + 4, z + 4, Blocks.yellow_flower, 0, 3);
        world.setBlock(x + 15, y + 4, z + 4, Blocks.fence, 0, 3);
        world.setBlock(x + 16, y + 4, z + 4, Blocks.air, 0, 3);
        world.setBlock(x, y + 4, z + 5, Blocks.air, 0, 3);
        world.setBlock(x + 1, y + 4, z + 5, Blocks.fence, 0, 3);
        world.setBlock(x + 2, y + 4, z + 5, Blocks.air, 0, 3);
        world.setBlock(x + 3, y + 4, z + 5, Blocks.air, 0, 3);
        world.setBlock(x + 4, y + 4, z + 5, Blocks.air, 0, 3);
        world.setBlock(x + 5, y + 4, z + 5, Blocks.air, 0, 3);
        world.setBlock(x + 6, y + 4, z + 5, Blocks.air, 0, 3);
        world.setBlock(x + 7, y + 4, z + 5, Blocks.air, 0, 3);
        world.setBlock(x + 8, y + 4, z + 5, Blocks.red_flower, 3, 3);
        world.setBlock(x + 9, y + 4, z + 5, Blocks.red_flower, 2, 3);
        world.setBlock(x + 10, y + 4, z + 5, Blocks.cobblestone, 0, 3);
        world.setBlock(x + 11, y + 4, z + 5, Blocks.air, 0, 3);
        world.setBlock(x + 12, y + 4, z + 5, Blocks.air, 0, 3);
        world.setBlock(x + 13, y + 4, z + 5, Blocks.cobblestone, 0, 3);
        world.setBlock(x + 14, y + 4, z + 5, Blocks.red_flower, 3, 3);
        world.setBlock(x + 15, y + 4, z + 5, Blocks.fence, 0, 3);
        world.setBlock(x + 16, y + 4, z + 5, Blocks.air, 0, 3);
        world.setBlock(x, y + 4, z + 6, Blocks.air, 0, 3);
        world.setBlock(x + 1, y + 4, z + 6, Blocks.log, 0, 3);
        world.setBlock(x + 2, y + 4, z + 6, Blocks.cobblestone, 0, 3);
        world.setBlock(x + 3, y + 4, z + 6, Blocks.cobblestone, 0, 3);
        world.setBlock(x + 4, y + 4, z + 6, Blocks.cobblestone, 0, 3);
        world.setBlock(x + 5, y + 4, z + 6, Blocks.cobblestone, 0, 3);
        world.setBlock(x + 6, y + 4, z + 6, Blocks.cobblestone, 0, 3);
        world.setBlock(x + 7, y + 4, z + 6, Blocks.cobblestone, 0, 3);
        world.setBlock(x + 8, y + 4, z + 6, Blocks.log, 0, 3);
        world.setBlock(x + 9, y + 4, z + 6, Blocks.cobblestone, 0, 3);
        world.setBlock(x + 10, y + 4, z + 6, Blocks.log, 0, 3);
        world.setBlock(x + 11, y + 4, z + 6, Blocks.air, 0, 3);
        world.setBlock(x + 12, y + 4, z + 6, Blocks.air, 0, 3);
        world.setBlock(x + 13, y + 4, z + 6, Blocks.log, 0, 3);
        world.setBlock(x + 14, y + 4, z + 6, Blocks.cobblestone, 0, 3);
        world.setBlock(x + 15, y + 4, z + 6, Blocks.log, 0, 3);
        world.setBlock(x + 16, y + 4, z + 6, Blocks.air, 0, 3);
        world.setBlock(x, y + 4, z + 7, Blocks.air, 0, 3);
        world.setBlock(x + 1, y + 4, z + 7, Blocks.cobblestone, 0, 3);
        world.setBlock(x + 2, y + 4, z + 7, Blocks.air, 0, 3);
        world.setBlock(x + 3, y + 4, z + 7, Blocks.air, 0, 3);
        world.setBlock(x + 4, y + 4, z + 7, Blocks.air, 0, 3);
        world.setBlock(x + 5, y + 4, z + 7, Blocks.air, 0, 3);
        world.setBlock(x + 6, y + 4, z + 7, Blocks.air, 0, 3);
        world.setBlock(x + 7, y + 4, z + 7, Blocks.air, 0, 3);
        world.setBlock(x + 8, y + 4, z + 7, Blocks.air, 0, 3);
        world.setBlock(x + 9, y + 4, z + 7, Blocks.air, 0, 3);
        world.setBlock(x + 10, y + 4, z + 7, Blocks.air, 0, 3);
        world.setBlock(x + 11, y + 4, z + 7, Blocks.air, 0, 3);
        world.setBlock(x + 12, y + 4, z + 7, Blocks.air, 0, 3);
        world.setBlock(x + 13, y + 4, z + 7, Blocks.air, 0, 3);
        world.setBlock(x + 14, y + 4, z + 7, Blocks.air, 0, 3);
        world.setBlock(x + 15, y + 4, z + 7, Blocks.cobblestone, 0, 3);
        world.setBlock(x + 16, y + 4, z + 7, Blocks.air, 0, 3);
        world.setBlock(x, y + 4, z + 8, Blocks.air, 0, 3);
        world.setBlock(x + 1, y + 4, z + 8, Blocks.cobblestone, 0, 3);
        world.setBlock(x + 2, y + 4, z + 8, Blocks.air, 0, 3);
        world.setBlock(x + 3, y + 4, z + 8, Blocks.gold_block, 0, 3);
        world.setBlock(x + 4, y + 4, z + 8, Blocks.gold_block, 0, 3);
        world.setBlock(x + 5, y + 4, z + 8, Blocks.gold_block, 0, 3);
        world.setBlock(x + 6, y + 4, z + 8, Blocks.gold_block, 0, 3);
        world.setBlock(x + 7, y + 4, z + 8, Blocks.gold_block, 0, 3);
        world.setBlock(x + 8, y + 4, z + 8, Blocks.air, 0, 3);
        world.setBlock(x + 9, y + 4, z + 8, Blocks.gold_block, 0, 3);
        world.setBlock(x + 10, y + 4, z + 8, Blocks.gold_block, 0, 3);
        world.setBlock(x + 11, y + 4, z + 8, Blocks.gold_block, 0, 3);
        world.setBlock(x + 12, y + 4, z + 8, Blocks.gold_block, 0, 3);
        world.setBlock(x + 13, y + 4, z + 8, Blocks.gold_block, 0, 3);
        world.setBlock(x + 14, y + 4, z + 8, Blocks.air, 0, 3);
        world.setBlock(x + 15, y + 4, z + 8, Blocks.cobblestone, 0, 3);
        world.setBlock(x + 16, y + 4, z + 8, Blocks.air, 0, 3);
        world.setBlock(x, y + 4, z + 9, Blocks.air, 0, 3);
        world.setBlock(x + 1, y + 4, z + 9, Blocks.log, 0, 3);
        world.setBlock(x + 2, y + 4, z + 9, Blocks.air, 0, 3);
        world.setBlock(x + 3, y + 4, z + 9, Blocks.gold_block, 0, 3);
        world.setBlock(x + 4, y + 4, z + 9, Blocks.gold_block, 0, 3);
        world.setBlock(x + 5, y + 4, z + 9, Blocks.gold_block, 0, 3);
        world.setBlock(x + 6, y + 4, z + 9, Blocks.gold_block, 0, 3);
        world.setBlock(x + 7, y + 4, z + 9, Blocks.gold_block, 0, 3);
        world.setBlock(x + 8, y + 4, z + 9, Blocks.air, 0, 3);
        world.setBlock(x + 9, y + 4, z + 9, Blocks.gold_block, 0, 3);
        world.setBlock(x + 10, y + 4, z + 9, Blocks.gold_block, 0, 3);
        world.setBlock(x + 11, y + 4, z + 9, Blocks.gold_block, 0, 3);
        world.setBlock(x + 12, y + 4, z + 9, Blocks.gold_block, 0, 3);
        world.setBlock(x + 13, y + 4, z + 9, Blocks.gold_block, 0, 3);
        world.setBlock(x + 14, y + 4, z + 9, Blocks.air, 0, 3);
        world.setBlock(x + 15, y + 4, z + 9, Blocks.log, 0, 3);
        world.setBlock(x + 16, y + 4, z + 9, Blocks.air, 0, 3);
        world.setBlock(x, y + 4, z + 10, Blocks.air, 0, 3);
        world.setBlock(x + 1, y + 4, z + 10, Blocks.wooden_door, 0, 3);
        world.setBlock(x + 2, y + 4, z + 10, Blocks.air, 0, 3);
        world.setBlock(x + 3, y + 4, z + 10, Blocks.gold_block, 0, 3);
        world.setBlock(x + 4, y + 4, z + 10, Blocks.gold_block, 0, 3);
        world.setBlock(x + 5, y + 4, z + 10, Blocks.gold_block, 0, 3);
        world.setBlock(x + 6, y + 4, z + 10, Blocks.gold_block, 0, 3);
        world.setBlock(x + 7, y + 4, z + 10, Blocks.gold_block, 0, 3);
        world.setBlock(x + 8, y + 4, z + 10, Blocks.air, 0, 3);
        world.setBlock(x + 9, y + 4, z + 10, Blocks.gold_block, 0, 3);
        world.setBlock(x + 10, y + 4, z + 10, Blocks.gold_block, 0, 3);
        world.setBlock(x + 11, y + 4, z + 10, Blocks.gold_block, 0, 3);
        world.setBlock(x + 12, y + 4, z + 10, Blocks.gold_block, 0, 3);
        world.setBlock(x + 13, y + 4, z + 10, Blocks.gold_block, 0, 3);
        world.setBlock(x + 14, y + 4, z + 10, Blocks.air, 0, 3);
        world.setBlock(x + 15, y + 4, z + 10, Blocks.wooden_door, 2, 3);
        world.setBlock(x + 16, y + 4, z + 10, Blocks.air, 0, 3);
        world.setBlock(x, y + 4, z + 11, Blocks.air, 0, 3);
        world.setBlock(x + 1, y + 4, z + 11, Blocks.log, 0, 3);
        world.setBlock(x + 2, y + 4, z + 11, Blocks.air, 0, 3);
        world.setBlock(x + 3, y + 4, z + 11, Blocks.gold_block, 0, 3);
        world.setBlock(x + 4, y + 4, z + 11, Blocks.gold_block, 0, 3);
        world.setBlock(x + 5, y + 4, z + 11, Blocks.gold_block, 0, 3);
        world.setBlock(x + 6, y + 4, z + 11, Blocks.gold_block, 0, 3);
        world.setBlock(x + 7, y + 4, z + 11, Blocks.gold_block, 0, 3);
        world.setBlock(x + 8, y + 4, z + 11, Blocks.air, 0, 3);
        world.setBlock(x + 9, y + 4, z + 11, Blocks.gold_block, 0, 3);
        world.setBlock(x + 10, y + 4, z + 11, Blocks.gold_block, 0, 3);
        world.setBlock(x + 11, y + 4, z + 11, Blocks.gold_block, 0, 3);
        world.setBlock(x + 12, y + 4, z + 11, Blocks.gold_block, 0, 3);
        world.setBlock(x + 13, y + 4, z + 11, Blocks.gold_block, 0, 3);
        world.setBlock(x + 14, y + 4, z + 11, Blocks.air, 0, 3);
        world.setBlock(x + 15, y + 4, z + 11, Blocks.log, 0, 3);
        world.setBlock(x + 16, y + 4, z + 11, Blocks.air, 0, 3);
        world.setBlock(x, y + 4, z + 12, Blocks.air, 0, 3);
        world.setBlock(x + 1, y + 4, z + 12, Blocks.cobblestone, 0, 3);
        world.setBlock(x + 2, y + 4, z + 12, Blocks.air, 0, 3);
        world.setBlock(x + 3, y + 4, z + 12, Blocks.gold_block, 0, 3);
        world.setBlock(x + 4, y + 4, z + 12, Blocks.gold_block, 0, 3);
        world.setBlock(x + 5, y + 4, z + 12, Blocks.gold_block, 0, 3);
        world.setBlock(x + 6, y + 4, z + 12, Blocks.gold_block, 0, 3);
        world.setBlock(x + 7, y + 4, z + 12, Blocks.gold_block, 0, 3);
        world.setBlock(x + 8, y + 4, z + 12, Blocks.air, 0, 3);
        world.setBlock(x + 9, y + 4, z + 12, Blocks.gold_block, 0, 3);
        world.setBlock(x + 10, y + 4, z + 12, Blocks.gold_block, 0, 3);
        world.setBlock(x + 11, y + 4, z + 12, Blocks.gold_block, 0, 3);
        world.setBlock(x + 12, y + 4, z + 12, Blocks.gold_block, 0, 3);
        world.setBlock(x + 13, y + 4, z + 12, Blocks.gold_block, 0, 3);
        world.setBlock(x + 14, y + 4, z + 12, Blocks.air, 0, 3);
        world.setBlock(x + 15, y + 4, z + 12, Blocks.cobblestone, 0, 3);
        world.setBlock(x + 16, y + 4, z + 12, Blocks.air, 0, 3);
        world.setBlock(x, y + 4, z + 13, Blocks.air, 0, 3);
        world.setBlock(x + 1, y + 4, z + 13, Blocks.cobblestone, 0, 3);
        world.setBlock(x + 2, y + 4, z + 13, Blocks.air, 0, 3);
        world.setBlock(x + 3, y + 4, z + 13, Blocks.air, 0, 3);
        world.setBlock(x + 4, y + 4, z + 13, Blocks.air, 0, 3);
        world.setBlock(x + 5, y + 4, z + 13, Blocks.air, 0, 3);
        world.setBlock(x + 6, y + 4, z + 13, Blocks.air, 0, 3);
        world.setBlock(x + 7, y + 4, z + 13, Blocks.air, 0, 3);
        world.setBlock(x + 8, y + 4, z + 13, Blocks.air, 0, 3);
        world.setBlock(x + 9, y + 4, z + 13, Blocks.air, 0, 3);
        world.setBlock(x + 10, y + 4, z + 13, Blocks.air, 0, 3);
        world.setBlock(x + 11, y + 4, z + 13, Blocks.air, 0, 3);
        world.setBlock(x + 12, y + 4, z + 13, Blocks.air, 0, 3);
        world.setBlock(x + 13, y + 4, z + 13, Blocks.air, 0, 3);
        world.setBlock(x + 14, y + 4, z + 13, Blocks.air, 0, 3);
        world.setBlock(x + 15, y + 4, z + 13, Blocks.cobblestone, 0, 3);
        world.setBlock(x + 16, y + 4, z + 13, Blocks.air, 0, 3);
        world.setBlock(x, y + 4, z + 14, Blocks.air, 0, 3);
        world.setBlock(x + 1, y + 4, z + 14, Blocks.log, 0, 3);
        world.setBlock(x + 2, y + 4, z + 14, Blocks.cobblestone, 0, 3);
        world.setBlock(x + 3, y + 4, z + 14, Blocks.cobblestone, 0, 3);
        world.setBlock(x + 4, y + 4, z + 14, Blocks.cobblestone, 0, 3);
        world.setBlock(x + 5, y + 4, z + 14, Blocks.cobblestone, 0, 3);
        world.setBlock(x + 6, y + 4, z + 14, Blocks.cobblestone, 0, 3);
        world.setBlock(x + 7, y + 4, z + 14, Blocks.cobblestone, 0, 3);
        world.setBlock(x + 8, y + 4, z + 14, Blocks.log, 0, 3);
        world.setBlock(x + 9, y + 4, z + 14, Blocks.cobblestone, 0, 3);
        world.setBlock(x + 10, y + 4, z + 14, Blocks.cobblestone, 0, 3);
        world.setBlock(x + 11, y + 4, z + 14, Blocks.cobblestone, 0, 3);
        world.setBlock(x + 12, y + 4, z + 14, Blocks.cobblestone, 0, 3);
        world.setBlock(x + 13, y + 4, z + 14, Blocks.cobblestone, 0, 3);
        world.setBlock(x + 14, y + 4, z + 14, Blocks.cobblestone, 0, 3);
        world.setBlock(x + 15, y + 4, z + 14, Blocks.log, 0, 3);
        world.setBlock(x + 16, y + 4, z + 14, Blocks.air, 0, 3);
        world.setBlock(x, y + 4, z + 15, Blocks.air, 0, 3);
        world.setBlock(x + 1, y + 4, z + 15, Blocks.air, 0, 3);
        world.setBlock(x + 2, y + 4, z + 15, Blocks.air, 0, 3);
        world.setBlock(x + 3, y + 4, z + 15, Blocks.air, 0, 3);
        world.setBlock(x + 4, y + 4, z + 15, Blocks.air, 0, 3);
        world.setBlock(x + 5, y + 4, z + 15, Blocks.air, 0, 3);
        world.setBlock(x + 6, y + 4, z + 15, Blocks.air, 0, 3);
        world.setBlock(x + 7, y + 4, z + 15, Blocks.air, 0, 3);
        world.setBlock(x + 8, y + 4, z + 15, Blocks.air, 0, 3);
        world.setBlock(x + 9, y + 4, z + 15, Blocks.air, 0, 3);
        world.setBlock(x + 10, y + 4, z + 15, Blocks.air, 0, 3);
        world.setBlock(x + 11, y + 4, z + 15, Blocks.air, 0, 3);
        world.setBlock(x + 12, y + 4, z + 15, Blocks.air, 0, 3);
        world.setBlock(x + 13, y + 4, z + 15, Blocks.air, 0, 3);
        world.setBlock(x + 14, y + 4, z + 15, Blocks.air, 0, 3);
        world.setBlock(x + 15, y + 4, z + 15, Blocks.air, 0, 3);
        world.setBlock(x + 16, y + 4, z + 15, Blocks.air, 0, 3);
        world.setBlock(x, y + 5, z, Blocks.air, 0, 3);
        world.setBlock(x + 1, y + 5, z, Blocks.air, 0, 3);
        world.setBlock(x + 2, y + 5, z, Blocks.air, 0, 3);
        world.setBlock(x + 3, y + 5, z, Blocks.air, 0, 3);
        world.setBlock(x + 4, y + 5, z, Blocks.air, 0, 3);
        world.setBlock(x + 5, y + 5, z, Blocks.air, 0, 3);
        world.setBlock(x + 6, y + 5, z, Blocks.air, 0, 3);
        world.setBlock(x + 7, y + 5, z, Blocks.air, 0, 3);
        world.setBlock(x + 8, y + 5, z, Blocks.air, 0, 3);
        world.setBlock(x + 9, y + 5, z, Blocks.air, 0, 3);
        world.setBlock(x + 10, y + 5, z, Blocks.air, 0, 3);
        world.setBlock(x + 11, y + 5, z, Blocks.air, 0, 3);
        world.setBlock(x + 12, y + 5, z, Blocks.air, 0, 3);
        world.setBlock(x + 13, y + 5, z, Blocks.air, 0, 3);
        world.setBlock(x + 14, y + 5, z, Blocks.air, 0, 3);
        world.setBlock(x + 15, y + 5, z, Blocks.air, 0, 3);
        world.setBlock(x + 16, y + 5, z, Blocks.air, 0, 3);
        world.setBlock(x, y + 5, z + 1, Blocks.air, 0, 3);
        world.setBlock(x + 2, y + 5, z + 1, Blocks.air, 0, 3);
        world.setBlock(x + 3, y + 5, z + 1, Blocks.planks, 0, 3);
        world.setBlock(x + 4, y + 5, z + 1, Blocks.air, 0, 3);
        world.setBlock(x + 5, y + 5, z + 1, Blocks.air, 0, 3);
        world.setBlock(x + 6, y + 5, z + 1, Blocks.planks, 0, 3);
        world.setBlock(x + 7, y + 5, z + 1, Blocks.air, 0, 3);
        world.setBlock(x + 8, y + 5, z + 1, Blocks.air, 0, 3);
        world.setBlock(x + 9, y + 5, z + 1, Blocks.air, 0, 3);
        world.setBlock(x + 10, y + 5, z + 1, Blocks.air, 0, 3);
        world.setBlock(x + 11, y + 5, z + 1, Blocks.air, 0, 3);
        world.setBlock(x + 12, y + 5, z + 1, Blocks.air, 0, 3);
        world.setBlock(x + 13, y + 5, z + 1, Blocks.air, 0, 3);
        world.setBlock(x + 14, y + 5, z + 1, Blocks.air, 0, 3);
        world.setBlock(x + 16, y + 5, z + 1, Blocks.air, 0, 3);
        world.setBlock(x, y + 5, z + 2, Blocks.air, 0, 3);
        world.setBlock(x + 1, y + 5, z + 2, Blocks.air, 0, 3);
        world.setBlock(x + 2, y + 5, z + 2, Blocks.air, 0, 3);
        world.setBlock(x + 3, y + 5, z + 2, Blocks.air, 0, 3);
        world.setBlock(x + 4, y + 5, z + 2, Blocks.air, 0, 3);
        world.setBlock(x + 5, y + 5, z + 2, Blocks.air, 0, 3);
        world.setBlock(x + 6, y + 5, z + 2, Blocks.air, 0, 3);
        world.setBlock(x + 7, y + 5, z + 2, Blocks.air, 0, 3);
        world.setBlock(x + 8, y + 5, z + 2, Blocks.air, 0, 3);
        world.setBlock(x + 9, y + 5, z + 2, Blocks.air, 0, 3);
        world.setBlock(x + 10, y + 5, z + 2, Blocks.air, 0, 3);
        world.setBlock(x + 11, y + 5, z + 2, Blocks.air, 0, 3);
        world.setBlock(x + 12, y + 5, z + 2, Blocks.air, 0, 3);
        world.setBlock(x + 13, y + 5, z + 2, Blocks.air, 0, 3);
        world.setBlock(x + 14, y + 5, z + 2, Blocks.air, 0, 3);
        world.setBlock(x + 15, y + 5, z + 2, Blocks.air, 0, 3);
        world.setBlock(x + 16, y + 5, z + 2, Blocks.air, 0, 3);
        world.setBlock(x, y + 5, z + 3, Blocks.air, 0, 3);
        world.setBlock(x + 1, y + 5, z + 3, Blocks.air, 0, 3);
        world.setBlock(x + 2, y + 5, z + 3, Blocks.air, 0, 3);
        world.setBlock(x + 3, y + 5, z + 3, Blocks.air, 0, 3);
        world.setBlock(x + 4, y + 5, z + 3, Blocks.air, 0, 3);
        world.setBlock(x + 5, y + 5, z + 3, Blocks.air, 0, 3);
        world.setBlock(x + 6, y + 5, z + 3, Blocks.air, 0, 3);
        world.setBlock(x + 7, y + 5, z + 3, Blocks.air, 0, 3);
        world.setBlock(x + 8, y + 5, z + 3, Blocks.air, 0, 3);
        world.setBlock(x + 9, y + 5, z + 3, Blocks.air, 0, 3);
        world.setBlock(x + 10, y + 5, z + 3, Blocks.log, 0, 3);
        world.setBlock(x + 11, y + 5, z + 3, Blocks.air, 0, 3);
        world.setBlock(x + 12, y + 5, z + 3, Blocks.air, 0, 3);
        world.setBlock(x + 13, y + 5, z + 3, Blocks.log, 0, 3);
        world.setBlock(x + 14, y + 5, z + 3, Blocks.air, 0, 3);
        world.setBlock(x + 15, y + 5, z + 3, Blocks.air, 0, 3);
        world.setBlock(x + 16, y + 5, z + 3, Blocks.air, 0, 3);
        world.setBlock(x, y + 5, z + 4, Blocks.air, 0, 3);
        world.setBlock(x + 1, y + 5, z + 4, Blocks.air, 0, 3);
        world.setBlock(x + 2, y + 5, z + 4, Blocks.air, 0, 3);
        world.setBlock(x + 3, y + 5, z + 4, Blocks.planks, 0, 3);
        world.setBlock(x + 4, y + 5, z + 4, Blocks.air, 0, 3);
        world.setBlock(x + 5, y + 5, z + 4, Blocks.air, 0, 3);
        world.setBlock(x + 6, y + 5, z + 4, Blocks.planks, 0, 3);
        world.setBlock(x + 7, y + 5, z + 4, Blocks.air, 0, 3);
        world.setBlock(x + 8, y + 5, z + 4, Blocks.air, 0, 3);
        world.setBlock(x + 9, y + 5, z + 4, Blocks.air, 0, 3);
        world.setBlock(x + 10, y + 5, z + 4, Blocks.air, 0, 3);
        world.setBlock(x + 11, y + 5, z + 4, Blocks.air, 0, 3);
        world.setBlock(x + 12, y + 5, z + 4, Blocks.air, 0, 3);
        world.setBlock(x + 13, y + 5, z + 4, Blocks.air, 0, 3);
        world.setBlock(x + 14, y + 5, z + 4, Blocks.air, 0, 3);
        world.setBlock(x + 15, y + 5, z + 4, Blocks.air, 0, 3);
        world.setBlock(x + 16, y + 5, z + 4, Blocks.air, 0, 3);
        world.setBlock(x, y + 5, z + 5, Blocks.air, 0, 3);
        world.setBlock(x + 1, y + 5, z + 5, Blocks.air, 0, 3);
        world.setBlock(x + 2, y + 5, z + 5, Blocks.air, 0, 3);
        world.setBlock(x + 3, y + 5, z + 5, Blocks.air, 0, 3);
        world.setBlock(x + 4, y + 5, z + 5, Blocks.air, 0, 3);
        world.setBlock(x + 5, y + 5, z + 5, Blocks.air, 0, 3);
        world.setBlock(x + 6, y + 5, z + 5, Blocks.air, 0, 3);
        world.setBlock(x + 7, y + 5, z + 5, Blocks.air, 0, 3);
        world.setBlock(x + 8, y + 5, z + 5, Blocks.air, 0, 3);
        world.setBlock(x + 9, y + 5, z + 5, Blocks.air, 0, 3);
        world.setBlock(x + 10, y + 5, z + 5, Blocks.air, 0, 3);
        world.setBlock(x + 11, y + 5, z + 5, Blocks.air, 0, 3);
        world.setBlock(x + 12, y + 5, z + 5, Blocks.air, 0, 3);
        world.setBlock(x + 13, y + 5, z + 5, Blocks.air, 0, 3);
        world.setBlock(x + 14, y + 5, z + 5, Blocks.air, 0, 3);
        world.setBlock(x + 15, y + 5, z + 5, Blocks.air, 0, 3);
        world.setBlock(x + 16, y + 5, z + 5, Blocks.air, 0, 3);
        world.setBlock(x, y + 5, z + 6, Blocks.air, 0, 3);
        world.setBlock(x + 1, y + 5, z + 6, Blocks.log, 0, 3);
        world.setBlock(x + 2, y + 5, z + 6, Blocks.glass, 0, 3);
        world.setBlock(x + 3, y + 5, z + 6, Blocks.log, 0, 3);
        world.setBlock(x + 4, y + 5, z + 6, Blocks.glass, 0, 3);
        world.setBlock(x + 5, y + 5, z + 6, Blocks.glass, 0, 3);
        world.setBlock(x + 6, y + 5, z + 6, Blocks.log, 0, 3);
        world.setBlock(x + 7, y + 5, z + 6, Blocks.glass, 0, 3);
        world.setBlock(x + 8, y + 5, z + 6, Blocks.log, 0, 3);
        world.setBlock(x + 9, y + 5, z + 6, Blocks.glass, 0, 3);
        world.setBlock(x + 10, y + 5, z + 6, Blocks.log, 0, 3);
        world.setBlock(x + 11, y + 5, z + 6, Blocks.air, 0, 3);
        world.setBlock(x + 12, y + 5, z + 6, Blocks.air, 0, 3);
        world.setBlock(x + 13, y + 5, z + 6, Blocks.log, 0, 3);
        world.setBlock(x + 14, y + 5, z + 6, Blocks.glass, 0, 3);
        world.setBlock(x + 15, y + 5, z + 6, Blocks.log, 0, 3);
        world.setBlock(x + 16, y + 5, z + 6, Blocks.air, 0, 3);
        world.setBlock(x, y + 5, z + 7, Blocks.air, 0, 3);
        world.setBlock(x + 1, y + 5, z + 7, Blocks.glass, 0, 3);
        world.setBlock(x + 2, y + 5, z + 7, Blocks.air, 0, 3);
        world.setBlock(x + 3, y + 5, z + 7, Blocks.air, 0, 3);
        world.setBlock(x + 4, y + 5, z + 7, Blocks.air, 0, 3);
        world.setBlock(x + 5, y + 5, z + 7, Blocks.air, 0, 3);
        world.setBlock(x + 6, y + 5, z + 7, Blocks.air, 0, 3);
        world.setBlock(x + 7, y + 5, z + 7, Blocks.air, 0, 3);
        world.setBlock(x + 8, y + 5, z + 7, Blocks.air, 0, 3);
        world.setBlock(x + 9, y + 5, z + 7, Blocks.air, 0, 3);
        world.setBlock(x + 10, y + 5, z + 7, Blocks.air, 0, 3);
        world.setBlock(x + 11, y + 5, z + 7, Blocks.air, 0, 3);
        world.setBlock(x + 12, y + 5, z + 7, Blocks.air, 0, 3);
        world.setBlock(x + 13, y + 5, z + 7, Blocks.air, 0, 3);
        world.setBlock(x + 14, y + 5, z + 7, Blocks.air, 0, 3);
        world.setBlock(x + 15, y + 5, z + 7, Blocks.glass, 0, 3);
        world.setBlock(x + 16, y + 5, z + 7, Blocks.air, 0, 3);
        world.setBlock(x, y + 5, z + 8, Blocks.air, 0, 3);
        world.setBlock(x + 1, y + 5, z + 8, Blocks.glass, 0, 3);
        world.setBlock(x + 2, y + 5, z + 8, Blocks.air, 0, 3);
        world.setBlock(x + 3, y + 5, z + 8, Blocks.air, 0, 3);
        world.setBlock(x + 4, y + 5, z + 8, Blocks.air, 0, 3);
        world.setBlock(x + 5, y + 5, z + 8, Blocks.air, 0, 3);
        world.setBlock(x + 6, y + 5, z + 8, Blocks.air, 0, 3);
        world.setBlock(x + 7, y + 5, z + 8, Blocks.air, 0, 3);
        world.setBlock(x + 8, y + 5, z + 8, Blocks.air, 0, 3);
        world.setBlock(x + 9, y + 5, z + 8, Blocks.air, 0, 3);
        world.setBlock(x + 10, y + 5, z + 8, Blocks.air, 0, 3);
        world.setBlock(x + 11, y + 5, z + 8, Blocks.air, 0, 3);
        world.setBlock(x + 12, y + 5, z + 8, Blocks.air, 0, 3);
        world.setBlock(x + 13, y + 5, z + 8, Blocks.air, 0, 3);
        world.setBlock(x + 14, y + 5, z + 8, Blocks.air, 0, 3);
        world.setBlock(x + 15, y + 5, z + 8, Blocks.glass, 0, 3);
        world.setBlock(x + 16, y + 5, z + 8, Blocks.air, 0, 3);
        world.setBlock(x, y + 5, z + 9, Blocks.air, 0, 3);
        world.setBlock(x + 1, y + 5, z + 9, Blocks.log, 0, 3);
        world.setBlock(x + 2, y + 5, z + 9, Blocks.air, 0, 3);
        world.setBlock(x + 3, y + 5, z + 9, Blocks.air, 0, 3);
        world.setBlock(x + 4, y + 5, z + 9, Blocks.air, 0, 3);
        world.setBlock(x + 5, y + 5, z + 9, Blocks.air, 0, 3);
        world.setBlock(x + 6, y + 5, z + 9, Blocks.air, 0, 3);
        world.setBlock(x + 7, y + 5, z + 9, Blocks.air, 0, 3);
        world.setBlock(x + 8, y + 5, z + 9, Blocks.air, 0, 3);
        world.setBlock(x + 9, y + 5, z + 9, Blocks.air, 0, 3);
        world.setBlock(x + 10, y + 5, z + 9, Blocks.air, 0, 3);
        world.setBlock(x + 11, y + 5, z + 9, Blocks.air, 0, 3);
        world.setBlock(x + 12, y + 5, z + 9, Blocks.air, 0, 3);
        world.setBlock(x + 13, y + 5, z + 9, Blocks.air, 0, 3);
        world.setBlock(x + 14, y + 5, z + 9, Blocks.air, 0, 3);
        world.setBlock(x + 15, y + 5, z + 9, Blocks.log, 0, 3);
        world.setBlock(x + 16, y + 5, z + 9, Blocks.air, 0, 3);
        world.setBlock(x, y + 5, z + 10, Blocks.air, 0, 3);
        world.setBlock(x + 1, y + 5, z + 10, Blocks.wooden_door, 8, 3);
        world.setBlock(x + 2, y + 5, z + 10, Blocks.air, 0, 3);
        world.setBlock(x + 3, y + 5, z + 10, Blocks.air, 0, 3);
        world.setBlock(x + 4, y + 5, z + 10, Blocks.air, 0, 3);
        world.setBlock(x + 5, y + 5, z + 10, Blocks.air, 0, 3);
        world.setBlock(x + 6, y + 5, z + 10, Blocks.air, 0, 3);
        world.setBlock(x + 7, y + 5, z + 10, Blocks.air, 0, 3);
        world.setBlock(x + 8, y + 5, z + 10, Blocks.air, 0, 3);
        world.setBlock(x + 9, y + 5, z + 10, Blocks.air, 0, 3);
        world.setBlock(x + 10, y + 5, z + 10, Blocks.air, 0, 3);
        world.setBlock(x + 11, y + 5, z + 10, Blocks.air, 0, 3);
        world.setBlock(x + 12, y + 5, z + 10, Blocks.air, 0, 3);
        world.setBlock(x + 13, y + 5, z + 10, Blocks.air, 0, 3);
        world.setBlock(x + 14, y + 5, z + 10, Blocks.air, 0, 3);
        world.setBlock(x + 15, y + 5, z + 10, Blocks.wooden_door, 8, 3);
        world.setBlock(x + 16, y + 5, z + 10, Blocks.air, 0, 3);
        world.setBlock(x, y + 5, z + 11, Blocks.air, 0, 3);
        world.setBlock(x + 1, y + 5, z + 11, Blocks.log, 0, 3);
        world.setBlock(x + 2, y + 5, z + 11, Blocks.air, 0, 3);
        world.setBlock(x + 3, y + 5, z + 11, Blocks.air, 0, 3);
        world.setBlock(x + 4, y + 5, z + 11, Blocks.air, 0, 3);
        world.setBlock(x + 5, y + 5, z + 11, Blocks.air, 0, 3);
        world.setBlock(x + 6, y + 5, z + 11, Blocks.air, 0, 3);
        world.setBlock(x + 7, y + 5, z + 11, Blocks.air, 0, 3);
        world.setBlock(x + 8, y + 5, z + 11, Blocks.air, 0, 3);
        world.setBlock(x + 9, y + 5, z + 11, Blocks.air, 0, 3);
        world.setBlock(x + 10, y + 5, z + 11, Blocks.air, 0, 3);
        world.setBlock(x + 11, y + 5, z + 11, Blocks.air, 0, 3);
        world.setBlock(x + 12, y + 5, z + 11, Blocks.air, 0, 3);
        world.setBlock(x + 13, y + 5, z + 11, Blocks.air, 0, 3);
        world.setBlock(x + 14, y + 5, z + 11, Blocks.air, 0, 3);
        world.setBlock(x + 15, y + 5, z + 11, Blocks.log, 0, 3);
        world.setBlock(x + 16, y + 5, z + 11, Blocks.air, 0, 3);
        world.setBlock(x, y + 5, z + 12, Blocks.air, 0, 3);
        world.setBlock(x + 1, y + 5, z + 12, Blocks.glass, 0, 3);
        world.setBlock(x + 2, y + 5, z + 12, Blocks.air, 0, 3);
        world.setBlock(x + 3, y + 5, z + 12, Blocks.air, 0, 3);
        world.setBlock(x + 4, y + 5, z + 12, Blocks.air, 0, 3);
        world.setBlock(x + 5, y + 5, z + 12, Blocks.air, 0, 3);
        world.setBlock(x + 6, y + 5, z + 12, Blocks.air, 0, 3);
        world.setBlock(x + 7, y + 5, z + 12, Blocks.air, 0, 3);
        world.setBlock(x + 8, y + 5, z + 12, Blocks.air, 0, 3);
        world.setBlock(x + 9, y + 5, z + 12, Blocks.air, 0, 3);
        world.setBlock(x + 10, y + 5, z + 12, Blocks.air, 0, 3);
        world.setBlock(x + 11, y + 5, z + 12, Blocks.air, 0, 3);
        world.setBlock(x + 12, y + 5, z + 12, Blocks.air, 0, 3);
        world.setBlock(x + 13, y + 5, z + 12, Blocks.air, 0, 3);
        world.setBlock(x + 14, y + 5, z + 12, Blocks.air, 0, 3);
        world.setBlock(x + 15, y + 5, z + 12, Blocks.glass, 0, 3);
        world.setBlock(x + 16, y + 5, z + 12, Blocks.air, 0, 3);
        world.setBlock(x, y + 5, z + 13, Blocks.air, 0, 3);
        world.setBlock(x + 1, y + 5, z + 13, Blocks.glass, 0, 3);
        world.setBlock(x + 2, y + 5, z + 13, Blocks.air, 0, 3);
        world.setBlock(x + 3, y + 5, z + 13, Blocks.air, 0, 3);
        world.setBlock(x + 4, y + 5, z + 13, Blocks.air, 0, 3);
        world.setBlock(x + 5, y + 5, z + 13, Blocks.air, 0, 3);
        world.setBlock(x + 6, y + 5, z + 13, Blocks.air, 0, 3);
        world.setBlock(x + 7, y + 5, z + 13, Blocks.air, 0, 3);
        world.setBlock(x + 8, y + 5, z + 13, Blocks.air, 0, 3);
        world.setBlock(x + 9, y + 5, z + 13, Blocks.air, 0, 3);
        world.setBlock(x + 10, y + 5, z + 13, Blocks.air, 0, 3);
        world.setBlock(x + 11, y + 5, z + 13, Blocks.air, 0, 3);
        world.setBlock(x + 12, y + 5, z + 13, Blocks.air, 0, 3);
        world.setBlock(x + 13, y + 5, z + 13, Blocks.air, 0, 3);
        world.setBlock(x + 14, y + 5, z + 13, Blocks.air, 0, 3);
        world.setBlock(x + 15, y + 5, z + 13, Blocks.glass, 0, 3);
        world.setBlock(x + 16, y + 5, z + 13, Blocks.air, 0, 3);
        world.setBlock(x, y + 5, z + 14, Blocks.air, 0, 3);
        world.setBlock(x + 1, y + 5, z + 14, Blocks.log, 0, 3);
        world.setBlock(x + 2, y + 5, z + 14, Blocks.glass, 0, 3);
        world.setBlock(x + 3, y + 5, z + 14, Blocks.glass, 0, 3);
        world.setBlock(x + 4, y + 5, z + 14, Blocks.glass, 0, 3);
        world.setBlock(x + 5, y + 5, z + 14, Blocks.glass, 0, 3);
        world.setBlock(x + 6, y + 5, z + 14, Blocks.glass, 0, 3);
        world.setBlock(x + 7, y + 5, z + 14, Blocks.glass, 0, 3);
        world.setBlock(x + 8, y + 5, z + 14, Blocks.log, 0, 3);
        world.setBlock(x + 9, y + 5, z + 14, Blocks.glass, 0, 3);
        world.setBlock(x + 10, y + 5, z + 14, Blocks.glass, 0, 3);
        world.setBlock(x + 11, y + 5, z + 14, Blocks.glass, 0, 3);
        world.setBlock(x + 12, y + 5, z + 14, Blocks.glass, 0, 3);
        world.setBlock(x + 13, y + 5, z + 14, Blocks.glass, 0, 3);
        world.setBlock(x + 14, y + 5, z + 14, Blocks.glass, 0, 3);
        world.setBlock(x + 15, y + 5, z + 14, Blocks.log, 0, 3);
        world.setBlock(x + 16, y + 5, z + 14, Blocks.air, 0, 3);
        world.setBlock(x, y + 5, z + 15, Blocks.air, 0, 3);
        world.setBlock(x + 1, y + 5, z + 15, Blocks.air, 0, 3);
        world.setBlock(x + 2, y + 5, z + 15, Blocks.air, 0, 3);
        world.setBlock(x + 3, y + 5, z + 15, Blocks.air, 0, 3);
        world.setBlock(x + 4, y + 5, z + 15, Blocks.air, 0, 3);
        world.setBlock(x + 5, y + 5, z + 15, Blocks.air, 0, 3);
        world.setBlock(x + 6, y + 5, z + 15, Blocks.air, 0, 3);
        world.setBlock(x + 7, y + 5, z + 15, Blocks.air, 0, 3);
        world.setBlock(x + 8, y + 5, z + 15, Blocks.air, 0, 3);
        world.setBlock(x + 9, y + 5, z + 15, Blocks.air, 0, 3);
        world.setBlock(x + 10, y + 5, z + 15, Blocks.air, 0, 3);
        world.setBlock(x + 11, y + 5, z + 15, Blocks.air, 0, 3);
        world.setBlock(x + 12, y + 5, z + 15, Blocks.air, 0, 3);
        world.setBlock(x + 13, y + 5, z + 15, Blocks.air, 0, 3);
        world.setBlock(x + 14, y + 5, z + 15, Blocks.air, 0, 3);
        world.setBlock(x + 15, y + 5, z + 15, Blocks.air, 0, 3);
        world.setBlock(x + 16, y + 5, z + 15, Blocks.air, 0, 3);
        world.setBlock(x, y + 6, z, Blocks.air, 0, 3);
        world.setBlock(x + 1, y + 6, z, Blocks.air, 0, 3);
        world.setBlock(x + 2, y + 6, z, Blocks.air, 0, 3);
        world.setBlock(x + 3, y + 6, z, Blocks.air, 0, 3);
        world.setBlock(x + 4, y + 6, z, Blocks.air, 0, 3);
        world.setBlock(x + 5, y + 6, z, Blocks.air, 0, 3);
        world.setBlock(x + 6, y + 6, z, Blocks.air, 0, 3);
        world.setBlock(x + 7, y + 6, z, Blocks.air, 0, 3);
        world.setBlock(x + 8, y + 6, z, Blocks.air, 0, 3);
        world.setBlock(x + 9, y + 6, z, Blocks.air, 0, 3);
        world.setBlock(x + 10, y + 6, z, Blocks.air, 0, 3);
        world.setBlock(x + 11, y + 6, z, Blocks.air, 0, 3);
        world.setBlock(x + 12, y + 6, z, Blocks.air, 0, 3);
        world.setBlock(x + 13, y + 6, z, Blocks.air, 0, 3);
        world.setBlock(x + 14, y + 6, z, Blocks.air, 0, 3);
        world.setBlock(x + 15, y + 6, z, Blocks.air, 0, 3);
        world.setBlock(x + 16, y + 6, z, Blocks.air, 0, 3);
        world.setBlock(x, y + 6, z + 1, Blocks.air, 0, 3);
        world.setBlock(x + 1, y + 6, z + 1, Blocks.air, 0, 3);
        world.setBlock(x + 2, y + 6, z + 1, Blocks.air, 0, 3);
        world.setBlock(x + 3, y + 6, z + 1, Blocks.planks, 0, 3);
        world.setBlock(x + 4, y + 6, z + 1, Blocks.oak_stairs, 5, 3);
        world.setBlock(x + 5, y + 6, z + 1, Blocks.oak_stairs, 4, 3);
        world.setBlock(x + 6, y + 6, z + 1, Blocks.planks, 0, 3);
        world.setBlock(x + 7, y + 6, z + 1, Blocks.air, 0, 3);
        world.setBlock(x + 8, y + 6, z + 1, Blocks.air, 0, 3);
        world.setBlock(x + 9, y + 6, z + 1, Blocks.air, 0, 3);
        world.setBlock(x + 10, y + 6, z + 1, Blocks.air, 0, 3);
        world.setBlock(x + 11, y + 6, z + 1, Blocks.air, 0, 3);
        world.setBlock(x + 12, y + 6, z + 1, Blocks.air, 0, 3);
        world.setBlock(x + 13, y + 6, z + 1, Blocks.air, 0, 3);
        world.setBlock(x + 14, y + 6, z + 1, Blocks.air, 0, 3);
        world.setBlock(x + 15, y + 6, z + 1, Blocks.air, 0, 3);
        world.setBlock(x + 16, y + 6, z + 1, Blocks.air, 0, 3);
        world.setBlock(x, y + 6, z + 2, Blocks.air, 0, 3);
        world.setBlock(x + 1, y + 6, z + 2, Blocks.air, 0, 3);
        world.setBlock(x + 2, y + 6, z + 2, Blocks.air, 0, 3);
        world.setBlock(x + 3, y + 6, z + 2, Blocks.oak_stairs, 7, 3);
        world.setBlock(x + 4, y + 6, z + 2, Blocks.air, 0, 3);
        world.setBlock(x + 5, y + 6, z + 2, Blocks.air, 0, 3);
        world.setBlock(x + 6, y + 6, z + 2, Blocks.oak_stairs, 7, 3);
        world.setBlock(x + 7, y + 6, z + 2, Blocks.air, 0, 3);
        world.setBlock(x + 8, y + 6, z + 2, Blocks.air, 0, 3);
        world.setBlock(x + 9, y + 6, z + 2, Blocks.air, 0, 3);
        world.setBlock(x + 11, y + 6, z + 2, Blocks.air, 0, 3);
        world.setBlock(x + 12, y + 6, z + 2, Blocks.air, 0, 3);
        world.setBlock(x + 14, y + 6, z + 2, Blocks.air, 0, 3);
        world.setBlock(x + 15, y + 6, z + 2, Blocks.air, 0, 3);
        world.setBlock(x + 16, y + 6, z + 2, Blocks.air, 0, 3);
        world.setBlock(x, y + 6, z + 3, Blocks.air, 0, 3);
        world.setBlock(x + 1, y + 6, z + 3, Blocks.air, 0, 3);
        world.setBlock(x + 2, y + 6, z + 3, Blocks.air, 0, 3);
        world.setBlock(x + 3, y + 6, z + 3, Blocks.oak_stairs, 6, 3);
        world.setBlock(x + 4, y + 6, z + 3, Blocks.air, 0, 3);
        world.setBlock(x + 5, y + 6, z + 3, Blocks.air, 0, 3);
        world.setBlock(x + 6, y + 6, z + 3, Blocks.oak_stairs, 6, 3);
        world.setBlock(x + 7, y + 6, z + 3, Blocks.air, 0, 3);
        world.setBlock(x + 8, y + 6, z + 3, Blocks.air, 0, 3);
        world.setBlock(x + 10, y + 6, z + 3, Blocks.log, 0, 3);
        world.setBlock(x + 11, y + 6, z + 3, Blocks.oak_stairs, 6, 3);
        world.setBlock(x + 12, y + 6, z + 3, Blocks.oak_stairs, 6, 3);
        world.setBlock(x + 13, y + 6, z + 3, Blocks.log, 0, 3);
        world.setBlock(x + 15, y + 6, z + 3, Blocks.air, 0, 3);
        world.setBlock(x + 16, y + 6, z + 3, Blocks.air, 0, 3);
        world.setBlock(x, y + 6, z + 4, Blocks.air, 0, 3);
        world.setBlock(x + 1, y + 6, z + 4, Blocks.air, 0, 3);
        world.setBlock(x + 2, y + 6, z + 4, Blocks.air, 0, 3);
        world.setBlock(x + 3, y + 6, z + 4, Blocks.planks, 0, 3);
        world.setBlock(x + 4, y + 6, z + 4, Blocks.oak_stairs, 5, 3);
        world.setBlock(x + 5, y + 6, z + 4, Blocks.oak_stairs, 4, 3);
        world.setBlock(x + 6, y + 6, z + 4, Blocks.planks, 0, 3);
        world.setBlock(x + 7, y + 6, z + 4, Blocks.air, 0, 3);
        world.setBlock(x + 8, y + 6, z + 4, Blocks.air, 0, 3);
        world.setBlock(x + 9, y + 6, z + 4, Blocks.air, 0, 3);
        world.setBlock(x + 10, y + 6, z + 4, Blocks.oak_stairs, 4, 3);
        world.setBlock(x + 11, y + 6, z + 4, Blocks.air, 0, 3);
        world.setBlock(x + 12, y + 6, z + 4, Blocks.air, 0, 3);
        world.setBlock(x + 13, y + 6, z + 4, Blocks.oak_stairs, 5, 3);
        world.setBlock(x + 14, y + 6, z + 4, Blocks.air, 0, 3);
        world.setBlock(x + 15, y + 6, z + 4, Blocks.air, 0, 3);
        world.setBlock(x + 16, y + 6, z + 4, Blocks.air, 0, 3);
        world.setBlock(x, y + 6, z + 5, Blocks.air, 0, 3);
        world.setBlock(x + 2, y + 6, z + 5, Blocks.air, 0, 3);
        world.setBlock(x + 3, y + 6, z + 5, Blocks.air, 0, 3);
        world.setBlock(x + 4, y + 6, z + 5, Blocks.air, 0, 3);
        world.setBlock(x + 5, y + 6, z + 5, Blocks.air, 0, 3);
        world.setBlock(x + 6, y + 6, z + 5, Blocks.air, 0, 3);
        world.setBlock(x + 7, y + 6, z + 5, Blocks.air, 0, 3);
        world.setBlock(x + 9, y + 6, z + 5, Blocks.air, 0, 3);
        world.setBlock(x + 10, y + 6, z + 5, Blocks.oak_stairs, 4, 3);
        world.setBlock(x + 11, y + 6, z + 5, Blocks.air, 0, 3);
        world.setBlock(x + 12, y + 6, z + 5, Blocks.air, 0, 3);
        world.setBlock(x + 13, y + 6, z + 5, Blocks.oak_stairs, 5, 3);
        world.setBlock(x + 14, y + 6, z + 5, Blocks.air, 0, 3);
        world.setBlock(x + 16, y + 6, z + 5, Blocks.air, 0, 3);
        world.setBlock(x + 1, y + 6, z + 6, Blocks.log, 0, 3);
        world.setBlock(x + 2, y + 6, z + 6, Blocks.glass, 0, 3);
        world.setBlock(x + 3, y + 6, z + 6, Blocks.log, 0, 3);
        world.setBlock(x + 4, y + 6, z + 6, Blocks.log, 4, 3);
        world.setBlock(x + 5, y + 6, z + 6, Blocks.log, 4, 3);
        world.setBlock(x + 6, y + 6, z + 6, Blocks.log, 0, 3);
        world.setBlock(x + 7, y + 6, z + 6, Blocks.glass, 0, 3);
        world.setBlock(x + 8, y + 6, z + 6, Blocks.log, 0, 3);
        world.setBlock(x + 9, y + 6, z + 6, Blocks.glass, 0, 3);
        world.setBlock(x + 10, y + 6, z + 6, Blocks.log, 0, 3);
        world.setBlock(x + 11, y + 6, z + 6, Blocks.log, 4, 3);
        world.setBlock(x + 12, y + 6, z + 6, Blocks.log, 4, 3);
        world.setBlock(x + 13, y + 6, z + 6, Blocks.log, 0, 3);
        world.setBlock(x + 14, y + 6, z + 6, Blocks.glass, 0, 3);
        world.setBlock(x + 15, y + 6, z + 6, Blocks.log, 0, 3);
        world.setBlock(x, y + 6, z + 7, Blocks.air, 0, 3);
        world.setBlock(x + 1, y + 6, z + 7, Blocks.glass, 0, 3);
        world.setBlock(x + 2, y + 6, z + 7, Blocks.air, 0, 3);
        world.setBlock(x + 3, y + 6, z + 7, Blocks.air, 0, 3);
        world.setBlock(x + 4, y + 6, z + 7, Blocks.air, 0, 3);
        world.setBlock(x + 5, y + 6, z + 7, Blocks.air, 0, 3);
        world.setBlock(x + 6, y + 6, z + 7, Blocks.air, 0, 3);
        world.setBlock(x + 7, y + 6, z + 7, Blocks.air, 0, 3);
        world.setBlock(x + 9, y + 6, z + 7, Blocks.air, 0, 3);
        world.setBlock(x + 11, y + 6, z + 7, Blocks.air, 0, 3);
        world.setBlock(x + 12, y + 6, z + 7, Blocks.air, 0, 3);
        world.setBlock(x + 14, y + 6, z + 7, Blocks.air, 0, 3);
        world.setBlock(x + 15, y + 6, z + 7, Blocks.glass, 0, 3);
        world.setBlock(x + 16, y + 6, z + 7, Blocks.air, 0, 3);
        world.setBlock(x, y + 6, z + 8, Blocks.air, 0, 3);
        world.setBlock(x + 1, y + 6, z + 8, Blocks.glass, 0, 3);
        world.setBlock(x + 2, y + 6, z + 8, Blocks.air, 0, 3);
        world.setBlock(x + 3, y + 6, z + 8, Blocks.air, 0, 3);
        world.setBlock(x + 4, y + 6, z + 8, Blocks.air, 0, 3);
        world.setBlock(x + 5, y + 6, z + 8, Blocks.air, 0, 3);
        world.setBlock(x + 6, y + 6, z + 8, Blocks.air, 0, 3);
        world.setBlock(x + 7, y + 6, z + 8, Blocks.air, 0, 3);
        world.setBlock(x + 8, y + 6, z + 8, Blocks.air, 0, 3);
        world.setBlock(x + 9, y + 6, z + 8, Blocks.air, 0, 3);
        world.setBlock(x + 10, y + 6, z + 8, Blocks.air, 0, 3);
        world.setBlock(x + 11, y + 6, z + 8, Blocks.air, 0, 3);
        world.setBlock(x + 12, y + 6, z + 8, Blocks.air, 0, 3);
        world.setBlock(x + 13, y + 6, z + 8, Blocks.air, 0, 3);
        world.setBlock(x + 14, y + 6, z + 8, Blocks.air, 0, 3);
        world.setBlock(x + 15, y + 6, z + 8, Blocks.glass, 0, 3);
        world.setBlock(x + 16, y + 6, z + 8, Blocks.air, 0, 3);
        world.setBlock(x + 1, y + 6, z + 9, Blocks.log, 0, 3);
        world.setBlock(x + 3, y + 6, z + 9, Blocks.air, 0, 3);
        world.setBlock(x + 4, y + 6, z + 9, Blocks.air, 0, 3);
        world.setBlock(x + 5, y + 6, z + 9, Blocks.air, 0, 3);
        world.setBlock(x + 6, y + 6, z + 9, Blocks.air, 0, 3);
        world.setBlock(x + 7, y + 6, z + 9, Blocks.air, 0, 3);
        world.setBlock(x + 8, y + 6, z + 9, Blocks.fence, 0, 3);
        world.setBlock(x + 9, y + 6, z + 9, Blocks.air, 0, 3);
        world.setBlock(x + 10, y + 6, z + 9, Blocks.air, 0, 3);
        world.setBlock(x + 11, y + 6, z + 9, Blocks.air, 0, 3);
        world.setBlock(x + 12, y + 6, z + 9, Blocks.air, 0, 3);
        world.setBlock(x + 13, y + 6, z + 9, Blocks.air, 0, 3);
        world.setBlock(x + 15, y + 6, z + 9, Blocks.log, 0, 3);
        world.setBlock(x, y + 6, z + 10, Blocks.air, 0, 3);
        world.setBlock(x + 1, y + 6, z + 10, Blocks.log, 8, 3);
        world.setBlock(x + 2, y + 6, z + 10, Blocks.air, 0, 3);
        world.setBlock(x + 3, y + 6, z + 10, Blocks.air, 0, 3);
        world.setBlock(x + 4, y + 6, z + 10, Blocks.air, 0, 3);
        world.setBlock(x + 5, y + 6, z + 10, Blocks.light_weighted_pressure_plate, 0, 3);
        world.setBlock(x + 6, y + 6, z + 10, Blocks.air, 0, 3);
        world.setBlock(x + 7, y + 6, z + 10, Blocks.air, 0, 3);
        world.setBlock(x + 8, y + 6, z + 10, Blocks.fence, 0, 3);
        world.setBlock(x + 9, y + 6, z + 10, Blocks.air, 0, 3);
        world.setBlock(x + 10, y + 6, z + 10, Blocks.air, 0, 3);
        world.setBlock(x + 11, y + 6, z + 10, Blocks.light_weighted_pressure_plate, 0, 3);
        world.setBlock(x + 12, y + 6, z + 10, Blocks.air, 0, 3);
        world.setBlock(x + 13, y + 6, z + 10, Blocks.air, 0, 3);
        world.setBlock(x + 14, y + 6, z + 10, Blocks.air, 0, 3);
        world.setBlock(x + 15, y + 6, z + 10, Blocks.log, 8, 3);
        world.setBlock(x + 16, y + 6, z + 10, Blocks.air, 0, 3);
        world.setBlock(x + 1, y + 6, z + 11, Blocks.log, 0, 3);
        world.setBlock(x + 3, y + 6, z + 11, Blocks.air, 0, 3);
        world.setBlock(x + 4, y + 6, z + 11, Blocks.air, 0, 3);
        world.setBlock(x + 5, y + 6, z + 11, Blocks.air, 0, 3);
        world.setBlock(x + 6, y + 6, z + 11, Blocks.air, 0, 3);
        world.setBlock(x + 7, y + 6, z + 11, Blocks.air, 0, 3);
        world.setBlock(x + 8, y + 6, z + 11, Blocks.fence, 0, 3);
        world.setBlock(x + 9, y + 6, z + 11, Blocks.air, 0, 3);
        world.setBlock(x + 10, y + 6, z + 11, Blocks.air, 0, 3);
        world.setBlock(x + 11, y + 6, z + 11, Blocks.air, 0, 3);
        world.setBlock(x + 12, y + 6, z + 11, Blocks.air, 0, 3);
        world.setBlock(x + 13, y + 6, z + 11, Blocks.air, 0, 3);
        world.setBlock(x + 15, y + 6, z + 11, Blocks.log, 0, 3);
        world.setBlock(x, y + 6, z + 12, Blocks.air, 0, 3);
        world.setBlock(x + 1, y + 6, z + 12, Blocks.glass, 0, 3);
        world.setBlock(x + 2, y + 6, z + 12, Blocks.air, 0, 3);
        world.setBlock(x + 3, y + 6, z + 12, Blocks.air, 0, 3);
        world.setBlock(x + 4, y + 6, z + 12, Blocks.air, 0, 3);
        world.setBlock(x + 5, y + 6, z + 12, Blocks.air, 0, 3);
        world.setBlock(x + 6, y + 6, z + 12, Blocks.air, 0, 3);
        world.setBlock(x + 7, y + 6, z + 12, Blocks.air, 0, 3);
        world.setBlock(x + 8, y + 6, z + 12, Blocks.air, 0, 3);
        world.setBlock(x + 9, y + 6, z + 12, Blocks.air, 0, 3);
        world.setBlock(x + 10, y + 6, z + 12, Blocks.air, 0, 3);
        world.setBlock(x + 11, y + 6, z + 12, Blocks.air, 0, 3);
        world.setBlock(x + 12, y + 6, z + 12, Blocks.air, 0, 3);
        world.setBlock(x + 13, y + 6, z + 12, Blocks.air, 0, 3);
        world.setBlock(x + 14, y + 6, z + 12, Blocks.air, 0, 3);
        world.setBlock(x + 15, y + 6, z + 12, Blocks.glass, 0, 3);
        world.setBlock(x + 16, y + 6, z + 12, Blocks.air, 0, 3);
        world.setBlock(x, y + 6, z + 13, Blocks.air, 0, 3);
        world.setBlock(x + 1, y + 6, z + 13, Blocks.glass, 0, 3);
        world.setBlock(x + 2, y + 6, z + 13, Blocks.air, 0, 3);
        world.setBlock(x + 3, y + 6, z + 13, Blocks.air, 0, 3);
        world.setBlock(x + 4, y + 6, z + 13, Blocks.air, 0, 3);
        world.setBlock(x + 5, y + 6, z + 13, Blocks.air, 0, 3);
        world.setBlock(x + 6, y + 6, z + 13, Blocks.air, 0, 3);
        world.setBlock(x + 7, y + 6, z + 13, Blocks.air, 0, 3);
        world.setBlock(x + 9, y + 6, z + 13, Blocks.air, 0, 3);
        world.setBlock(x + 10, y + 6, z + 13, Blocks.air, 0, 3);
        world.setBlock(x + 11, y + 6, z + 13, Blocks.air, 0, 3);
        world.setBlock(x + 12, y + 6, z + 13, Blocks.air, 0, 3);
        world.setBlock(x + 13, y + 6, z + 13, Blocks.air, 0, 3);
        world.setBlock(x + 14, y + 6, z + 13, Blocks.air, 0, 3);
        world.setBlock(x + 15, y + 6, z + 13, Blocks.glass, 0, 3);
        world.setBlock(x + 16, y + 6, z + 13, Blocks.air, 0, 3);
        world.setBlock(x + 1, y + 6, z + 14, Blocks.log, 0, 3);
        world.setBlock(x + 2, y + 6, z + 14, Blocks.glass, 0, 3);
        world.setBlock(x + 3, y + 6, z + 14, Blocks.glass, 0, 3);
        world.setBlock(x + 4, y + 6, z + 14, Blocks.glass, 0, 3);
        world.setBlock(x + 5, y + 6, z + 14, Blocks.glass, 0, 3);
        world.setBlock(x + 6, y + 6, z + 14, Blocks.glass, 0, 3);
        world.setBlock(x + 7, y + 6, z + 14, Blocks.glass, 0, 3);
        world.setBlock(x + 8, y + 6, z + 14, Blocks.log, 0, 3);
        world.setBlock(x + 9, y + 6, z + 14, Blocks.glass, 0, 3);
        world.setBlock(x + 10, y + 6, z + 14, Blocks.glass, 0, 3);
        world.setBlock(x + 11, y + 6, z + 14, Blocks.glass, 0, 3);
        world.setBlock(x + 12, y + 6, z + 14, Blocks.glass, 0, 3);
        world.setBlock(x + 13, y + 6, z + 14, Blocks.glass, 0, 3);
        world.setBlock(x + 14, y + 6, z + 14, Blocks.glass, 0, 3);
        world.setBlock(x + 15, y + 6, z + 14, Blocks.log, 0, 3);
        world.setBlock(x, y + 6, z + 15, Blocks.air, 0, 3);
        world.setBlock(x + 2, y + 6, z + 15, Blocks.air, 0, 3);
        world.setBlock(x + 3, y + 6, z + 15, Blocks.air, 0, 3);
        world.setBlock(x + 4, y + 6, z + 15, Blocks.air, 0, 3);
        world.setBlock(x + 5, y + 6, z + 15, Blocks.air, 0, 3);
        world.setBlock(x + 6, y + 6, z + 15, Blocks.air, 0, 3);
        world.setBlock(x + 7, y + 6, z + 15, Blocks.air, 0, 3);
        world.setBlock(x + 9, y + 6, z + 15, Blocks.air, 0, 3);
        world.setBlock(x + 10, y + 6, z + 15, Blocks.air, 0, 3);
        world.setBlock(x + 11, y + 6, z + 15, Blocks.air, 0, 3);
        world.setBlock(x + 12, y + 6, z + 15, Blocks.air, 0, 3);
        world.setBlock(x + 13, y + 6, z + 15, Blocks.air, 0, 3);
        world.setBlock(x + 14, y + 6, z + 15, Blocks.air, 0, 3);
        world.setBlock(x + 16, y + 6, z + 15, Blocks.air, 0, 3);
        world.setBlock(x, y + 7, z, Blocks.air, 0, 3);
        world.setBlock(x + 1, y + 7, z, Blocks.air, 0, 3);
        world.setBlock(x + 2, y + 7, z, Blocks.air, 0, 3);
        world.setBlock(x + 3, y + 7, z, Blocks.air, 0, 3);
        world.setBlock(x + 4, y + 7, z, Blocks.air, 0, 3);
        world.setBlock(x + 5, y + 7, z, Blocks.air, 0, 3);
        world.setBlock(x + 6, y + 7, z, Blocks.air, 0, 3);
        world.setBlock(x + 7, y + 7, z, Blocks.air, 0, 3);
        world.setBlock(x + 8, y + 7, z, Blocks.air, 0, 3);
        world.setBlock(x + 9, y + 7, z, Blocks.air, 0, 3);
        world.setBlock(x + 10, y + 7, z, Blocks.air, 0, 3);
        world.setBlock(x + 11, y + 7, z, Blocks.air, 0, 3);
        world.setBlock(x + 12, y + 7, z, Blocks.air, 0, 3);
        world.setBlock(x + 13, y + 7, z, Blocks.air, 0, 3);
        world.setBlock(x + 14, y + 7, z, Blocks.air, 0, 3);
        world.setBlock(x + 15, y + 7, z, Blocks.air, 0, 3);
        world.setBlock(x + 16, y + 7, z, Blocks.air, 0, 3);
        world.setBlock(x, y + 7, z + 1, Blocks.air, 0, 3);
        world.setBlock(x + 1, y + 7, z + 1, Blocks.air, 0, 3);
        world.setBlock(x + 2, y + 7, z + 1, Blocks.air, 0, 3);
        world.setBlock(x + 3, y + 7, z + 1, Blocks.iron_block, 0, 3);
        world.setBlock(x + 4, y + 7, z + 1, Blocks.iron_block, 0, 3);
        world.setBlock(x + 5, y + 7, z + 1, Blocks.iron_block, 0, 3);
        world.setBlock(x + 6, y + 7, z + 1, Blocks.iron_block, 0, 3);
        world.setBlock(x + 7, y + 7, z + 1, Blocks.air, 0, 3);
        world.setBlock(x + 8, y + 7, z + 1, Blocks.air, 0, 3);
        world.setBlock(x + 9, y + 7, z + 1, Blocks.air, 0, 3);
        world.setBlock(x + 10, y + 7, z + 1, Blocks.air, 0, 3);
        world.setBlock(x + 11, y + 7, z + 1, Blocks.air, 0, 3);
        world.setBlock(x + 12, y + 7, z + 1, Blocks.air, 0, 3);
        world.setBlock(x + 13, y + 7, z + 1, Blocks.air, 0, 3);
        world.setBlock(x + 14, y + 7, z + 1, Blocks.air, 0, 3);
        world.setBlock(x + 15, y + 7, z + 1, Blocks.air, 0, 3);
        world.setBlock(x + 16, y + 7, z + 1, Blocks.air, 0, 3);
        world.setBlock(x, y + 7, z + 2, Blocks.air, 0, 3);
        world.setBlock(x + 1, y + 7, z + 2, Blocks.air, 0, 3);
        world.setBlock(x + 2, y + 7, z + 2, Blocks.air, 0, 3);
        world.setBlock(x + 3, y + 7, z + 2, Blocks.iron_block, 0, 3);
        world.setBlock(x + 4, y + 7, z + 2, Blocks.iron_block, 0, 3);
        world.setBlock(x + 5, y + 7, z + 2, Blocks.iron_block, 0, 3);
        world.setBlock(x + 6, y + 7, z + 2, Blocks.iron_block, 0, 3);
        world.setBlock(x + 7, y + 7, z + 2, Blocks.air, 0, 3);
        world.setBlock(x + 8, y + 7, z + 2, Blocks.air, 0, 3);
        world.setBlock(x + 9, y + 7, z + 2, Blocks.air, 0, 3);
        world.setBlock(x + 10, y + 7, z + 2, Blocks.air, 0, 3);
        world.setBlock(x + 11, y + 7, z + 2, Blocks.air, 0, 3);
        world.setBlock(x + 12, y + 7, z + 2, Blocks.air, 0, 3);
        world.setBlock(x + 13, y + 7, z + 2, Blocks.air, 0, 3);
        world.setBlock(x + 14, y + 7, z + 2, Blocks.air, 0, 3);
        world.setBlock(x + 15, y + 7, z + 2, Blocks.air, 0, 3);
        world.setBlock(x + 16, y + 7, z + 2, Blocks.air, 0, 3);
        world.setBlock(x, y + 7, z + 3, Blocks.air, 0, 3);
        world.setBlock(x + 1, y + 7, z + 3, Blocks.air, 0, 3);
        world.setBlock(x + 2, y + 7, z + 3, Blocks.air, 0, 3);
        world.setBlock(x + 3, y + 7, z + 3, Blocks.iron_block, 0, 3);
        world.setBlock(x + 4, y + 7, z + 3, Blocks.iron_block, 0, 3);
        world.setBlock(x + 5, y + 7, z + 3, Blocks.iron_block, 0, 3);
